Workbook
Name BlanksRangeExp: 'רשימת הסעיפים'!$AA$4:$AA$323
Name BlanksRangeInc: 'רשימת הסעיפים'!$AB$4:$AB$63
Name ExpCare: טבלה11[טיפוח]
Name ExpCloth: טבלה8[ביגוד והנעלה]
Name ExpCom: טבלה17[תקשורת]
Name ExpCommit: טבלה19[התחייבויות]
Name ExpEdu: טבלה12[חינוך]
Name ExpEvents: טבלה13[אירועים, תרומות, צרכי דת]
Name ExpFamily: טבלה16[משפחה]
Name ExpFin: טבלה21[פיננסים]
Name ExpFood: טבלה4[מזון ופארמה]
Name ExpHealth: טבלה14[בריאות]
Name ExpHobby: טבלה7[פנאי, בילוי ותחביבים]
Name ExpHome: טבלה10[אחזקת בית]
Name ExpHomeCont: טבלה9[תכולת בית]
Name ExpHousing: טבלה18[דיור]
Name ExpMainList: 'רשימת הסעיפים'!$AG$4:$AG$20
Name ExpProp: טבלה20[נכסים]
Name ExpTransp: טבלה15[תחבורה]
Name IncAllow: טבלה23[קצבאות]
Name IncMainList: 'רשימת הסעיפים'!$AG$21:$AG$24
Name IncMisc: טבלה24[הכנסות שונות]
Name Incomes: OFFSET(#REF!,0,0,COUNTA(#REF!),1)
Name IncSal: טבלה22[שכר]
Name NoBlanksExp: 'רשימת הסעיפים'!$AC$3:$AC$323
Name NoBlanksInc: 'רשימת הסעיפים'!$AD$3:$AD$62
Name Outcomes: OFFSET(#REF!,0,0,COUNTA(#REF!),1)
Name PrivateIncomes: OFFSET(#REF!,0,0,COUNTA(#REF!),1)
Name PrivateOutcomes: OFFSET(#REF!,0,0,COUNTA(#REF!),1)
Name טבלת_ימי_החודש: #REF!
Name טבלת_נתוני_מקור: #REF!
Name טבלת_נתוני_מקור_להכנסות: #REF!
Name טבלת_קטגוריות: #REF!
Name טבלת_שמות_החודשים: #REF!
Name ללא_בחירה: #REF!
Name סעיפי_הכנסות: #REF!
Name סעיפי_חובות: #REF!
Name סעיפי_חודשיות_קבועות: #REF!
Name סעיפי_שוטפות: #REF!
Name סעיפי_תקופתיות: #REF!
Name ריקה: #REF!
Name תשלום_שלא_כובד: #REF!

Sheet הדרכה
B1: שמיר - כלי לשיקוף מהיר וביצוע על בסיס פירוט פעולות בנק וכרטיס אשראי באמצעות האפ-עמון
D2: גירסה
D3: אפעמון 021123
B4: הכנה | C4: הורידו את פירוט החיובים/התנועות לחודשים שלמים מכל חשבונות הבנק וכרטיסי האשראי של המשפחה (הורידו בפורמט אקסל). במקרה של שיקוף - על מספר החודשים מכל המקורות להיות זהה.
B5: שלב א | C5: הטעינו את האפ-עמון בקבצים שהורדתם לפי ההוראות שבמדריך לאפ-עמון
B6: שלב ב | C6: ודאו שהקבצים הוטענו במלואם לשמיר באמצעות גיליון "שמיר" בקובץ זה ועברו לגיליון 'שלב ב - סיווג התנועות' ובצעו את ההוראות שבו. במידת הצורך תוכלו להוסיף שמות סעיפים פרטיים בגיליון 'רשימת הסעיפים' וכן הוסיפו שורות עבור הפעולות שבוצעו במזומן במהלך תקופת השיקוף/ביצוע
B7: שלב ג | C7: בחנו את תוצאות השיקוף/ביצוע בגיליון שלב ג'.
B8: בסיום | C8: שמרו את הקובץ המסווג בפורמט XLS (אקסל 97-2003). בצעו מתוך תוכנת פעמונים, יבוא אוטומטי של תוצאות השיקוף (תיק המשפחה -> שיקוף וביצועים -> יבוא שיקוף חדש).
B9: לאחר העברת התוצאות לתוכנת פעמונים, השלימו בה את השיקוף ע"י הוספת: הכנסות/הוצאות שלא נכללו בתקופה שבדפי התנועות נתוני סעיפים פרטיים (אם יצרתם כאלו), חובות וחסכונות
B11: נתונים שהועתקו מאתרי הבנק והאשראי הדורשים התייחסות מיוחדת: עסקה המהווה החזר חוב:להשאיר את התנועה ללא סיווג לסעיף. לשקול להוסיף את התנועה כחוב במודול החובות בתיק המשפחה. עסקת תשלומים: לפי העניין - לרשום כחוב או כהוצאה בהתאם לאופי התשלום נתונים כפולים: אין לסווג את רשומות האשראי שבתנועות העו"ש. מטבע זר: יש לוודא שהסכום שהועתק הוא במונחים של ש"ח ואם לא יש להמיר את הסכום לש"ח

Sheet שלב א - טעינת דפי מקור

Sheet שלב ב - סיווג תנועות
A1: שם המשפחה | B1: ישראלי | P1: חודשי/מזדמן | Q1: ='שלב ב - סיווג תנועות'!B2 -> 0
A2: תקופת השיקוף | P2: שנתי | Q2: 12 | AD2: שורה ראשונה להדבקה ביעד | AF2: שם המקור האחרון | AH2: מקור אחרון שנבחר | AI2: 1
A3: ממוצע הוצאות בחודש | B3: ='שלב ג - תוצאות השיקוף'!B2 -> 0 | P3: דו-חודשי | Q3: 2 | AD3: 9 | AF3: =AH3 & " - " & INDIRECT("'שלב א - טעינת דפי מקור'!" & VLOOKUP($AH$3,'שלב ב - סיווג תנועות'!AD6:AJ23,7,0)) -> בנק אגוד - | AH3: =IF(AND(AI2=2,'שלב א - טעינת דפי מקור'!F4 = "יתרת פתיחה"),AD19,INDEX(AD6:AD23,AI2)) -> בנק אגוד | AI3: =VLOOKUP(AH3,AR6:AS23,2,0) -> Igud
A4: ממוצע הכנסות בחודש | B4: ='שלב ג - תוצאות השיקוף'!E2 -> 0 | O4: הוצאה | P4: רבעוני | Q4: 3
A5: מאזן חודשי | B5: =(B4-B3) -> 0 | O5: הכנסה | P5: חלוקת הסכום ב X (רשמו כאן את X) | AC5: לא נתמכים עדיין | AE5: עמודה לתאריך | AF5: עמודה לתיאור | AG5: עמודה לסכום [חובה] | AH5: עמודה לפרטים/הערות | AJ5: תא למיקום שם מקור | AL5: שורת נתונים ראשונה | AM5: שורת נתונים אחרונה | AN5: מס' שורות להעתיק | AR5: תרגום למשתמשי אקסל באנגלית
A6: שימו לב! אין לשנות את סדר התנועות או את מיקומן. | AD6: בנק אגוד | AE6: A | AF6: B | AG6: D | AJ6: A5 | AL6: 23 | AM6: =MATCH(100000000000,'שלב א - טעינת דפי מקור'!F:F) -> #N/A | AN6: =AM6-AL6 -> #N/A | AR6: בנק אגוד | AS6: Igud
A7: תנועות מתוך דפי בנק וכרטיסי אשראי | AD7: בנק אוצר החייל | AE7: B | AF7: D | AG7: G | AJ7: A1 | AL7: 3 | AM7: =MATCH(100000000000,'שלב א - טעינת דפי מקור'!C:C) -> #N/A | AN7: =AM7-AL7 -> #N/A | AR7: בנק אוצר החייל | AS7: Otsar
A8: מקור | B8: תאריך | C8: תיאור / שם בית העסק | D8: סכום | E8: הוצאה/הכנסה (ברירת מחדל: הוצאה) | F8: מחזוריות (ברירת מחדל: חודשי/מזדמן) | G8: סעיף ראשי | H8: שם סעיף | I8: הערות (מלל חופשי) | J8: סכום עסקה | K8: מטבע לחיוב | L8: מספר כרטיס/בנק | N8: לממוצע חודשי (לשימוש פנימי) | O8: מס' חודשים (לשימוש פנימי) | P8: מס' מופעים (לשימוש פנימי) | AD8: בנק דיסקונט | AE8: A | AF8: C | AG8: D | AJ8: A6 | AL8: 14 | AM8: =MATCH(100000000000,'שלב א - טעינת דפי מקור'!E:E) -> #N/A | AN8: =AM8-AL8 -> #N/A | AR8: בנק דיסקונט | AS8: Discount
A9: אשראי-1 | B9: 01/01/2026 | C9: פיצה מתי קניון רחובות | D9: 22 | E9: הוצאה | F9: ="" | G9: פנאי, בילוי ותחביבים | H9: מסעדה ואוכל בחוץ | J9: 22 | K9: ₪ | L9: 7721 | N9: =IF(OR(F9=$P$1,F9="",F9=0),D9/$B$2,IF(OR(F9=$P$2,F9=$P$3,F9=$P$4),D9/(O9*P9),D9/O9)) -> #DIV/0! | O9: =IFERROR(VLOOKUP(F9,$P$1:$Q$4,2,0),F9) | P9: =IF(C9="",1,COUNTIFS($C$9:$C$1499,C9,$H$9:$H$1499,H9)) -> 1 | AD9: בנק הפועלים (עסקי) | AE9: A | AF9: C | AG9: G | AH9: D | AJ9: A5 | AL9: 7 | AM9: =MATCH(100000000000,'שלב א - טעינת דפי מקור'!I:I) -> #N/A | AN9: =AM9-AL9 -> #N/A | AR9: בנק הפועלים (עסקי) | AS9: PoalimBiz
A10: אשראי-1 | B10: 01/01/2026 | C10: רבידים המרכז לחינוך ופיתו | D10: 80 | E10: הוצאה | F10: =IFERROR(VLOOKUP(C10,$C$9:H9,4,FALSE),"") | G10: =IFERROR(VLOOKUP(C10,$C$9:G9,5,FALSE),"") | H10: =IFERROR(VLOOKUP(C10,$C$9:H9,6,FALSE),"") | I10: הוראת קבע | J10: 80 | K10: ₪ | L10: 7721 | N10: =IF(OR(F10=$P$1,F10="",F10=0),D10/$B$2,IF(OR(F10=$P$2,F10=$P$3,F10=$P$4),D10/(O10*P10),D10/O10)) -> #DIV/0! | O10: =IFERROR(VLOOKUP(F10,$P$1:$Q$4,2,0),F10) | P10: =IF(C10="",1,COUNTIFS($C$9:$C$1499,C10,$H$9:$H$1499,H10)) -> 1 | AD10: בנק הפועלים | AE10: A | AF10: B | AG10: E | AH10: C | AJ10: A5 | AL10: 7 | AM10: =MATCH(100000000000,'שלב א - טעינת דפי מקור'!G:G) -> #N/A | AN10: =AM10-AL10 -> #N/A | AR10: בנק הפועלים | AS10: Poalim
A11: אשראי-1 | B11: 01/01/2026 | C11: KSP רחובות | D11: 72 | E11: הוצאה | F11: =IFERROR(VLOOKUP(C11,$C$9:H10,4,FALSE),"") | G11: =IFERROR(VLOOKUP(C11,$C$9:G10,5,FALSE),"") | H11: =IFERROR(VLOOKUP(C11,$C$9:H10,6,FALSE),"") | J11: 72 | K11: ₪ | L11: 7721 | N11: =IF(OR(F11=$P$1,F11="",F11=0),D11/$B$2,IF(OR(F11=$P$2,F11=$P$3,F11=$P$4),D11/(O11*P11),D11/O11)) -> #DIV/0! | O11: =IFERROR(VLOOKUP(F11,$P$1:$Q$4,2,0),F11) | P11: =IF(C11="",1,COUNTIFS($C$9:$C$1499,C11,$H$9:$H$1499,H11)) -> 1 | AD11: בנק יהב | AE11: A | AF11: D | AG11: E | AJ11: B4 | AL11: 7 | AM11: =MATCH(100000000000,'שלב א - טעינת דפי מקור'!A:A) -> #N/A | AN11: =AM11-AL11 -> #N/A | AR11: בנק יהב | AS11: Yahav
A12: אשראי-1 | B12: 01/01/2026 | C12: KSP רחובות | D12: 108 | E12: הוצאה | F12: =IFERROR(VLOOKUP(C12,$C$9:H11,4,FALSE),"") | G12: =IFERROR(VLOOKUP(C12,$C$9:G11,5,FALSE),"") | H12: =IFERROR(VLOOKUP(C12,$C$9:H11,6,FALSE),"") | J12: 108 | K12: ₪ | L12: 7721 | N12: =IF(OR(F12=$P$1,F12="",F12=0),D12/$B$2,IF(OR(F12=$P$2,F12=$P$3,F12=$P$4),D12/(O12*P12),D12/O12)) -> #DIV/0! | O12: =IFERROR(VLOOKUP(F12,$P$1:$Q$4,2,0),F12) | P12: =IF(C12="",1,COUNTIFS($C$9:$C$1499,C12,$H$9:$H$1499,H12)) -> 1 | AC12: בנק ירושלים | AD12: ----- שמור זמנית ----- | AR12: ----- שמור זמנית ----- | AS12: Reserved
A13: אשראי-1 | B13: 01/01/2026 | C13: WOLT | D13: 36.99 | E13: הוצאה | F13: =IFERROR(VLOOKUP(C13,$C$9:H12,4,FALSE),"") | G13: פנאי, בילוי ותחביבים | H13: מסעדה ואוכל בחוץ | J13: 36.99 | K13: ₪ | L13: 7721 | N13: =IF(OR(F13=$P$1,F13="",F13=0),D13/$B$2,IF(OR(F13=$P$2,F13=$P$3,F13=$P$4),D13/(O13*P13),D13/O13)) -> #DIV/0! | O13: =IFERROR(VLOOKUP(F13,$P$1:$Q$4,2,0),F13) | P13: =IF(C13="",1,COUNTIFS($C$9:$C$1499,C13,$H$9:$H$1499,H13)) -> 1 | AD13: בנק לאומי | AE13: A | AF13: C | AG13: E | AH13: H | AJ13: A2 | AL13: =MATCH("תיאור",'שלב א - טעינת דפי מקור'!$C$1:$C$27,0)+1 -> #N/A | AM13: =MATCH(100000000000,'שלב א - טעינת דפי מקור'!D:D) -> #N/A | AN13: =AM13-AL13 -> #N/A | AR13: בנק לאומי | AS13: Leumi
A14: אשראי-1 | B14: 01/01/2026 | C14: פיס פלוס -תו נטען | D14: 37.5 | E14: הוצאה | F14: =IFERROR(VLOOKUP(C14,$C$9:H13,4,FALSE),"") | G14: =IFERROR(VLOOKUP(C14,$C$9:G13,5,FALSE),"") | H14: =IFERROR(VLOOKUP(C14,$C$9:H13,6,FALSE),"") | J14: 37.5 | K14: ₪ | L14: 7721 | N14: =IF(OR(F14=$P$1,F14="",F14=0),D14/$B$2,IF(OR(F14=$P$2,F14=$P$3,F14=$P$4),D14/(O14*P14),D14/O14)) -> #DIV/0! | O14: =IFERROR(VLOOKUP(F14,$P$1:$Q$4,2,0),F14) | P14: =IF(C14="",1,COUNTIFS($C$9:$C$1499,C14,$H$9:$H$1499,H14)) -> 1 | AD14: בנק מזרחי טפחות | AE14: A | AF14: C | AG14: E | AJ14: B3 | AL14: 11 | AM14: =MATCH(100000000000,'שלב א - טעינת דפי מקור'!G:G) -> #N/A | AN14: =AM14-AL14 -> #N/A | AR14: בנק מזרחי טפחות | AS14: Mizrachi
A15: אשראי-1 | B15: 01/01/2026 | C15: פיס פלוס -תו נטען | D15: 187.5 | E15: הוצאה | F15: =IFERROR(VLOOKUP(C15,$C$9:H14,4,FALSE),"") | G15: =IFERROR(VLOOKUP(C15,$C$9:G14,5,FALSE),"") | H15: =IFERROR(VLOOKUP(C15,$C$9:H14,6,FALSE),"") | J15: 187.5 | K15: ₪ | L15: 7721 | N15: =IF(OR(F15=$P$1,F15="",F15=0),D15/$B$2,IF(OR(F15=$P$2,F15=$P$3,F15=$P$4),D15/(O15*P15),D15/O15)) -> #DIV/0! | O15: =IFERROR(VLOOKUP(F15,$P$1:$Q$4,2,0),F15) | P15: =IF(C15="",1,COUNTIFS($C$9:$C$1499,C15,$H$9:$H$1499,H15)) -> 1 | AD15: בנק מסד | AE15: B | AF15: D | AG15: G | AJ15: A1 | AL15: 4 | AM15: =MATCH(100000000000,'שלב א - טעינת דפי מקור'!C:C) -> #N/A | AN15: =AM15-AL15 -> #N/A | AR15: בנק מסד | AS15: Masad
A16: אשראי-1 | B16: 01/01/2026 | C16: WOLT | D16: 49 | E16: הוצאה | F16: =IFERROR(VLOOKUP(C16,$C$9:H15,4,FALSE),"") | G16: פנאי, בילוי ותחביבים | H16: מסעדה ואוכל בחוץ | J16: 49 | K16: ₪ | L16: 7721 | N16: =IF(OR(F16=$P$1,F16="",F16=0),D16/$B$2,IF(OR(F16=$P$2,F16=$P$3,F16=$P$4),D16/(O16*P16),D16/O16)) -> #DIV/0! | O16: =IFERROR(VLOOKUP(F16,$P$1:$Q$4,2,0),F16) | P16: =IF(C16="",1,COUNTIFS($C$9:$C$1499,C16,$H$9:$H$1499,H16)) -> 1 | AD16: בנק מרכנתיל דיסקונט | AE16: A | AF16: C | AG16: D | AJ16: A3 | AL16: 9 | AM16: =IFERROR(MATCH(AO16,'שלב א - טעינת דפי מקור'!A:A,0)-2,MATCH(100000000000,'שלב א - טעינת דפי מקור'!E:E)) -> #N/A | AN16: =AM16-AL16 -> #N/A | AO16: תנועות עתידיות | AR16: בנק מרכנתיל דיסקונט | AS16: Mercantil
A17: אשראי-1 | B17: 01/01/2026 | C17: הטבות פיס | D17: 26 | E17: הוצאה | F17: =IFERROR(VLOOKUP(C17,$C$9:H16,4,FALSE),"") | G17: =IFERROR(VLOOKUP(C17,$C$9:G16,5,FALSE),"") | H17: =IFERROR(VLOOKUP(C17,$C$9:H16,6,FALSE),"") | J17: 26 | K17: ₪ | L17: 7721 | N17: =IF(OR(F17=$P$1,F17="",F17=0),D17/$B$2,IF(OR(F17=$P$2,F17=$P$3,F17=$P$4),D17/(O17*P17),D17/O17)) -> #DIV/0! | O17: =IFERROR(VLOOKUP(F17,$P$1:$Q$4,2,0),F17) | P17: =IF(C17="",1,COUNTIFS($C$9:$C$1499,C17,$H$9:$H$1499,H17)) -> 1 | AC17: בנק ערבי ישראלי | AD17: ----- שמור זמנית -----
A18: אשראי-1 | B18: 01/01/2026 | C18: הטבות פיס פ. | D18: 135 | E18: הוצאה | F18: =IFERROR(VLOOKUP(C18,$C$9:H17,4,FALSE),"") | G18: =IFERROR(VLOOKUP(C18,$C$9:G17,5,FALSE),"") | H18: =IFERROR(VLOOKUP(C18,$C$9:H17,6,FALSE),"") | J18: 135 | K18: ₪ | L18: 7721 | N18: =IF(OR(F18=$P$1,F18="",F18=0),D18/$B$2,IF(OR(F18=$P$2,F18=$P$3,F18=$P$4),D18/(O18*P18),D18/O18)) -> #DIV/0! | O18: =IFERROR(VLOOKUP(F18,$P$1:$Q$4,2,0),F18) | P18: =IF(C18="",1,COUNTIFS($C$9:$C$1499,C18,$H$9:$H$1499,H18)) -> 1 | AC18: בנק פועלי אגודת ישראל | AD18: ----- שמור זמנית -----
A19: אשראי-1 | B19: 01/01/2026 | C19: הטבות פיס פ. | D19: 99 | E19: הוצאה | F19: =IFERROR(VLOOKUP(C19,$C$9:H18,4,FALSE),"") | G19: =IFERROR(VLOOKUP(C19,$C$9:G18,5,FALSE),"") | H19: =IFERROR(VLOOKUP(C19,$C$9:H18,6,FALSE),"") | J19: 99 | K19: ₪ | L19: 7721 | N19: =IF(OR(F19=$P$1,F19="",F19=0),D19/$B$2,IF(OR(F19=$P$2,F19=$P$3,F19=$P$4),D19/(O19*P19),D19/O19)) -> #DIV/0! | O19: =IFERROR(VLOOKUP(F19,$P$1:$Q$4,2,0),F19) | P19: =IF(C19="",1,COUNTIFS($C$9:$C$1499,C19,$H$9:$H$1499,H19)) -> 1 | AD19: הבנק הבינלאומי הראשון | AE19: I | AF19: F | AG19: E | AJ19: A1 | AL19: 5 | AM19: =MATCH(100000000000,'שלב א - טעינת דפי מקור'!H:H) -> #N/A | AN19: =AM19-AL19 -> #N/A | AR19: הבנק הבינלאומי הראשון | AS19: BenLeumi
A20: אשראי-1 | B20: 01/01/2026 | C20: הטבות פיס פ. | D20: 150 | E20: הוצאה | F20: =IFERROR(VLOOKUP(C20,$C$9:H19,4,FALSE),"") | G20: =IFERROR(VLOOKUP(C20,$C$9:G19,5,FALSE),"") | H20: =IFERROR(VLOOKUP(C20,$C$9:H19,6,FALSE),"") | J20: 150 | K20: ₪ | L20: 7721 | N20: =IF(OR(F20=$P$1,F20="",F20=0),D20/$B$2,IF(OR(F20=$P$2,F20=$P$3,F20=$P$4),D20/(O20*P20),D20/O20)) -> #DIV/0! | O20: =IFERROR(VLOOKUP(F20,$P$1:$Q$4,2,0),F20) | P20: =IF(C20="",1,COUNTIFS($C$9:$C$1499,C20,$H$9:$H$1499,H20)) -> 1 | AC20: יובנק | AD20: ----- שמור זמנית -----
A21: אשראי-1 | B21: 01/01/2026 | C21: הטבות פיס פ. | D21: 118 | E21: הוצאה | F21: =IFERROR(VLOOKUP(C21,$C$9:H20,4,FALSE),"") | G21: =IFERROR(VLOOKUP(C21,$C$9:G20,5,FALSE),"") | H21: =IFERROR(VLOOKUP(C21,$C$9:H20,6,FALSE),"") | J21: 118 | K21: ₪ | L21: 7721 | N21: =IF(OR(F21=$P$1,F21="",F21=0),D21/$B$2,IF(OR(F21=$P$2,F21=$P$3,F21=$P$4),D21/(O21*P21),D21/O21)) -> #DIV/0! | O21: =IFERROR(VLOOKUP(F21,$P$1:$Q$4,2,0),F21) | P21: =IF(C21="",1,COUNTIFS($C$9:$C$1499,C21,$H$9:$H$1499,H21)) -> 1 | AD21: כרטיס ישראכרט | AE21: A | AF21: B | AG21: C | AH21: H | AJ21: A4 | AL21: 7 | AM21: =IFERROR(MATCH(AO21,'שלב א - טעינת דפי מקור'!A:A,0)-2,MATCH(100000000000,'שלב א - טעינת דפי מקור'!E:E)-1) -> #N/A | AN21: =AM21-AL21 -> #N/A | AO21: עסקאות בחו˝ל | AP21: =IFERROR(MATCH(AO21,'שלב א - טעינת דפי מקור'!A:A,0),"None") -> None | AR21: כרטיס ישראכרט | AS21: Isracard
A22: בנק-11 | B22: 01/01/2026 | C22: הו"ק הלו' רבית | D22: 103.44 | E22: הוצאה | F22: =IFERROR(VLOOKUP(C22,$C$9:H21,4,FALSE),"") | G22: =IFERROR(VLOOKUP(C22,$C$9:G21,5,FALSE),"") | H22: =IFERROR(VLOOKUP(C22,$C$9:H21,6,FALSE),"") | J22: 0 | L22: 12-615-563159 | N22: =IF(OR(F22=$P$1,F22="",F22=0),D22/$B$2,IF(OR(F22=$P$2,F22=$P$3,F22=$P$4),D22/(O22*P22),D22/O22)) -> #DIV/0! | O22: =IFERROR(VLOOKUP(F22,$P$1:$Q$4,2,0),F22) | P22: =IF(C22="",1,COUNTIFS($C$9:$C$1499,C22,$H$9:$H$1499,H22)) -> 1 | AD22: כרטיס כ.א.ל | AE22: A | AF22: B | AG22: C | AH22: E | AJ22: A2 | AL22: 4 | AM22: =MATCH(100000000000,'שלב א - טעינת דפי מקור'!D:D)-1 -> #N/A | AN22: =AM22-AL22 -> #N/A | AR22: כרטיס כ.א.ל | AS22: Cal
A23: בנק-11 | B23: 01/01/2026 | C23: הו"ק הלואה קרן | D23: 442.26 | E23: הוצאה | F23: =IFERROR(VLOOKUP(C23,$C$9:H22,4,FALSE),"") | G23: =IFERROR(VLOOKUP(C23,$C$9:G22,5,FALSE),"") | H23: =IFERROR(VLOOKUP(C23,$C$9:H22,6,FALSE),"") | J23: 0 | L23: 12-615-563159 | N23: =IF(OR(F23=$P$1,F23="",F23=0),D23/$B$2,IF(OR(F23=$P$2,F23=$P$3,F23=$P$4),D23/(O23*P23),D23/O23)) -> #DIV/0! | O23: =IFERROR(VLOOKUP(F23,$P$1:$Q$4,2,0),F23) | P23: =IF(C23="",1,COUNTIFS($C$9:$C$1499,C23,$H$9:$H$1499,H23)) -> 1 | AD23: כרטיס מקס (לאומי קארד) | AE23: A | AF23: B | AG23: H | AH23: K | AJ23: D5 | AL23: 5 | AM23: =MATCH(100000000000,'שלב א - טעינת דפי מקור'!F:F) -> #N/A | AN23: =AM23-AL23 -> #N/A | AR23: כרטיס מקס (לאומי קארד) | AS23: MaxCard
A24: אשראי-1 | B24: 02/01/2026 | C24: קפה לנדוור בע"מ | D24: 130 | E24: הוצאה | F24: =IFERROR(VLOOKUP(C24,$C$9:H23,4,FALSE),"") | G24: פנאי, בילוי ותחביבים | H24: מסעדה ואוכל בחוץ | J24: 130 | K24: ₪ | L24: 7721 | N24: =IF(OR(F24=$P$1,F24="",F24=0),D24/$B$2,IF(OR(F24=$P$2,F24=$P$3,F24=$P$4),D24/(O24*P24),D24/O24)) -> #DIV/0! | O24: =IFERROR(VLOOKUP(F24,$P$1:$Q$4,2,0),F24) | P24: =IF(C24="",1,COUNTIFS($C$9:$C$1499,C24,$H$9:$H$1499,H24)) -> 1 | AC24: בנק דקסיה ישראל
A25: אשראי-1 | B25: 02/01/2026 | C25: פיצה מתי קניון רחובות | D25: 34 | E25: הוצאה | F25: =IFERROR(VLOOKUP(C25,$C$9:H24,4,FALSE),"") | G25: פנאי, בילוי ותחביבים | H25: מסעדה ואוכל בחוץ | J25: 34 | K25: ₪ | L25: 7721 | N25: =IF(OR(F25=$P$1,F25="",F25=0),D25/$B$2,IF(OR(F25=$P$2,F25=$P$3,F25=$P$4),D25/(O25*P25),D25/O25)) -> #DIV/0! | O25: =IFERROR(VLOOKUP(F25,$P$1:$Q$4,2,0),F25) | P25: =IF(C25="",1,COUNTIFS($C$9:$C$1499,C25,$H$9:$H$1499,H25)) -> 1
A26: אשראי-1 | B26: 02/01/2026 | C26: צ'וקה רחובות | D26: 15 | E26: הוצאה | F26: =IFERROR(VLOOKUP(C26,$C$9:H25,4,FALSE),"") | G26: פנאי, בילוי ותחביבים | H26: מסעדה ואוכל בחוץ | J26: 15 | K26: ₪ | L26: 7721 | N26: =IF(OR(F26=$P$1,F26="",F26=0),D26/$B$2,IF(OR(F26=$P$2,F26=$P$3,F26=$P$4),D26/(O26*P26),D26/O26)) -> #DIV/0! | O26: =IFERROR(VLOOKUP(F26,$P$1:$Q$4,2,0),F26) | P26: =IF(C26="",1,COUNTIFS($C$9:$C$1499,C26,$H$9:$H$1499,H26)) -> 1
A27: אשראי-1 | B27: 02/01/2026 | C27: ביגה ראשונים | D27: 38.8 | E27: הוצאה | F27: =IFERROR(VLOOKUP(C27,$C$9:H26,4,FALSE),"") | G27: =IFERROR(VLOOKUP(C27,$C$9:G26,5,FALSE),"") | H27: =IFERROR(VLOOKUP(C27,$C$9:H26,6,FALSE),"") | J27: 40 | K27: ₪ | L27: 7721 | N27: =IF(OR(F27=$P$1,F27="",F27=0),D27/$B$2,IF(OR(F27=$P$2,F27=$P$3,F27=$P$4),D27/(O27*P27),D27/O27)) -> #DIV/0! | O27: =IFERROR(VLOOKUP(F27,$P$1:$Q$4,2,0),F27) | P27: =IF(C27="",1,COUNTIFS($C$9:$C$1499,C27,$H$9:$H$1499,H27)) -> 1
A28: אשראי-1 | B28: 02/01/2026 | C28: הטבות פיס פ. | D28: 50 | E28: הוצאה | F28: =IFERROR(VLOOKUP(C28,$C$9:H27,4,FALSE),"") | G28: =IFERROR(VLOOKUP(C28,$C$9:G27,5,FALSE),"") | H28: =IFERROR(VLOOKUP(C28,$C$9:H27,6,FALSE),"") | J28: 50 | K28: ₪ | L28: 7721 | N28: =IF(OR(F28=$P$1,F28="",F28=0),D28/$B$2,IF(OR(F28=$P$2,F28=$P$3,F28=$P$4),D28/(O28*P28),D28/O28)) -> #DIV/0! | O28: =IFERROR(VLOOKUP(F28,$P$1:$Q$4,2,0),F28) | P28: =IF(C28="",1,COUNTIFS($C$9:$C$1499,C28,$H$9:$H$1499,H28)) -> 1
A29: אשראי-1 | B29: 02/01/2026 | C29: הטבות פיס פ. | D29: 190 | E29: הוצאה | F29: =IFERROR(VLOOKUP(C29,$C$9:H28,4,FALSE),"") | G29: =IFERROR(VLOOKUP(C29,$C$9:G28,5,FALSE),"") | H29: =IFERROR(VLOOKUP(C29,$C$9:H28,6,FALSE),"") | J29: 190 | K29: ₪ | L29: 7721 | N29: =IF(OR(F29=$P$1,F29="",F29=0),D29/$B$2,IF(OR(F29=$P$2,F29=$P$3,F29=$P$4),D29/(O29*P29),D29/O29)) -> #DIV/0! | O29: =IFERROR(VLOOKUP(F29,$P$1:$Q$4,2,0),F29) | P29: =IF(C29="",1,COUNTIFS($C$9:$C$1499,C29,$H$9:$H$1499,H29)) -> 1
A30: אשראי-1 | B30: 02/01/2026 | C30: אורבן קופיקס בע"מ רחובות | D30: 8 | E30: הוצאה | F30: =IFERROR(VLOOKUP(C30,$C$9:H29,4,FALSE),"") | G30: =IFERROR(VLOOKUP(C30,$C$9:G29,5,FALSE),"") | H30: =IFERROR(VLOOKUP(C30,$C$9:H29,6,FALSE),"") | J30: 8 | K30: ₪ | L30: 7721 | N30: =IF(OR(F30=$P$1,F30="",F30=0),D30/$B$2,IF(OR(F30=$P$2,F30=$P$3,F30=$P$4),D30/(O30*P30),D30/O30)) -> #DIV/0! | O30: =IFERROR(VLOOKUP(F30,$P$1:$Q$4,2,0),F30) | P30: =IF(C30="",1,COUNTIFS($C$9:$C$1499,C30,$H$9:$H$1499,H30)) -> 1
A31: אשראי-1 | B31: 02/01/2026 | C31: WOLT | D31: 10.1 | E31: הוצאה | F31: =IFERROR(VLOOKUP(C31,$C$9:H30,4,FALSE),"") | G31: פנאי, בילוי ותחביבים | H31: מסעדה ואוכל בחוץ | J31: 10.1 | K31: ₪ | L31: 7721 | N31: =IF(OR(F31=$P$1,F31="",F31=0),D31/$B$2,IF(OR(F31=$P$2,F31=$P$3,F31=$P$4),D31/(O31*P31),D31/O31)) -> #DIV/0! | O31: =IFERROR(VLOOKUP(F31,$P$1:$Q$4,2,0),F31) | P31: =IF(C31="",1,COUNTIFS($C$9:$C$1499,C31,$H$9:$H$1499,H31)) -> 1
A32: אשראי-1 | B32: 02/01/2026 | C32: פיס פלוס -תו נטען | D32: 37.5 | E32: הוצאה | F32: =IFERROR(VLOOKUP(C32,$C$9:H31,4,FALSE),"") | G32: =IFERROR(VLOOKUP(C32,$C$9:G31,5,FALSE),"") | H32: =IFERROR(VLOOKUP(C32,$C$9:H31,6,FALSE),"") | J32: 37.5 | K32: ₪ | L32: 7721 | N32: =IF(OR(F32=$P$1,F32="",F32=0),D32/$B$2,IF(OR(F32=$P$2,F32=$P$3,F32=$P$4),D32/(O32*P32),D32/O32)) -> #DIV/0! | O32: =IFERROR(VLOOKUP(F32,$P$1:$Q$4,2,0),F32) | P32: =IF(C32="",1,COUNTIFS($C$9:$C$1499,C32,$H$9:$H$1499,H32)) -> 1
A33: בנק-11 | B33: 02/01/2026 | C33: הו"ק הלו' רבית | D33: 124.71 | E33: הוצאה | F33: =IFERROR(VLOOKUP(C33,$C$9:H32,4,FALSE),"") | G33: =IFERROR(VLOOKUP(C33,$C$9:G32,5,FALSE),"") | H33: =IFERROR(VLOOKUP(C33,$C$9:H32,6,FALSE),"") | J33: 0 | L33: 12-615-563159 | N33: =IF(OR(F33=$P$1,F33="",F33=0),D33/$B$2,IF(OR(F33=$P$2,F33=$P$3,F33=$P$4),D33/(O33*P33),D33/O33)) -> #DIV/0! | O33: =IFERROR(VLOOKUP(F33,$P$1:$Q$4,2,0),F33) | P33: =IF(C33="",1,COUNTIFS($C$9:$C$1499,C33,$H$9:$H$1499,H33)) -> 1
A34: בנק-11 | B34: 02/01/2026 | C34: הו"ק הלואה קרן | D34: 330.81 | E34: הוצאה | F34: =IFERROR(VLOOKUP(C34,$C$9:H33,4,FALSE),"") | G34: =IFERROR(VLOOKUP(C34,$C$9:G33,5,FALSE),"") | H34: =IFERROR(VLOOKUP(C34,$C$9:H33,6,FALSE),"") | J34: 0 | L34: 12-615-563159 | N34: =IF(OR(F34=$P$1,F34="",F34=0),D34/$B$2,IF(OR(F34=$P$2,F34=$P$3,F34=$P$4),D34/(O34*P34),D34/O34)) -> #DIV/0! | O34: =IFERROR(VLOOKUP(F34,$P$1:$Q$4,2,0),F34) | P34: =IF(C34="",1,COUNTIFS($C$9:$C$1499,C34,$H$9:$H$1499,H34)) -> 1
A35: בנק-11 | B35: 02/01/2026 | C35: מקס איט פיננסי | D35: 7628.75 | E35: הוצאה | F35: =IFERROR(VLOOKUP(C35,$C$9:H34,4,FALSE),"") | G35: לא לסיווג | H35: לא לסיווג | J35: 0 | L35: 12-615-563159 | N35: =IF(OR(F35=$P$1,F35="",F35=0),D35/$B$2,IF(OR(F35=$P$2,F35=$P$3,F35=$P$4),D35/(O35*P35),D35/O35)) -> #DIV/0! | O35: =IFERROR(VLOOKUP(F35,$P$1:$Q$4,2,0),F35) | P35: =IF(C35="",1,COUNTIFS($C$9:$C$1499,C35,$H$9:$H$1499,H35)) -> 1
A36: בנק-11 | B36: 02/01/2026 | C36: משיכה מבנקט | D36: 200 | E36: הוצאה | F36: =IFERROR(VLOOKUP(C36,$C$9:H35,4,FALSE),"") | G36: =IFERROR(VLOOKUP(C36,$C$9:G35,5,FALSE),"") | H36: =IFERROR(VLOOKUP(C36,$C$9:H35,6,FALSE),"") | J36: 0 | L36: 12-615-563159 | N36: =IF(OR(F36=$P$1,F36="",F36=0),D36/$B$2,IF(OR(F36=$P$2,F36=$P$3,F36=$P$4),D36/(O36*P36),D36/O36)) -> #DIV/0! | O36: =IFERROR(VLOOKUP(F36,$P$1:$Q$4,2,0),F36) | P36: =IF(C36="",1,COUNTIFS($C$9:$C$1499,C36,$H$9:$H$1499,H36)) -> 1
A37: בנק-11 | B37: 02/01/2026 | C37: כאל | D37: 4551.98 | E37: הוצאה | F37: =IFERROR(VLOOKUP(C37,$C$9:H36,4,FALSE),"") | G37: =IFERROR(VLOOKUP(C37,$C$9:G36,5,FALSE),"") | H37: =IFERROR(VLOOKUP(C37,$C$9:H36,6,FALSE),"") | J37: 0 | L37: 12-615-563159 | N37: =IF(OR(F37=$P$1,F37="",F37=0),D37/$B$2,IF(OR(F37=$P$2,F37=$P$3,F37=$P$4),D37/(O37*P37),D37/O37)) -> #DIV/0! | O37: =IFERROR(VLOOKUP(F37,$P$1:$Q$4,2,0),F37) | P37: =IF(C37="",1,COUNTIFS($C$9:$C$1499,C37,$H$9:$H$1499,H37)) -> 1
A38: אשראי-1 | B38: 03/01/2026 | C38: ביחד בשבילך | D38: 76 | E38: הוצאה | F38: =IFERROR(VLOOKUP(C38,$C$9:H37,4,FALSE),"") | G38: =IFERROR(VLOOKUP(C38,$C$9:G37,5,FALSE),"") | H38: =IFERROR(VLOOKUP(C38,$C$9:H37,6,FALSE),"") | J38: 76 | K38: ₪ | L38: 7721 | N38: =IF(OR(F38=$P$1,F38="",F38=0),D38/$B$2,IF(OR(F38=$P$2,F38=$P$3,F38=$P$4),D38/(O38*P38),D38/O38)) -> #DIV/0! | O38: =IFERROR(VLOOKUP(F38,$P$1:$Q$4,2,0),F38) | P38: =IF(C38="",1,COUNTIFS($C$9:$C$1499,C38,$H$9:$H$1499,H38)) -> 1
A39: אשראי-1 | B39: 03/01/2026 | C39: סופרפארם אונליין | D39: 50.83 | E39: הוצאה | F39: =IFERROR(VLOOKUP(C39,$C$9:H38,4,FALSE),"") | G39: מזון ופארמה | H39: פארמה וטואלטיקה | J39: 50.83 | K39: ₪ | L39: 7721 | N39: =IF(OR(F39=$P$1,F39="",F39=0),D39/$B$2,IF(OR(F39=$P$2,F39=$P$3,F39=$P$4),D39/(O39*P39),D39/O39)) -> #DIV/0! | O39: =IFERROR(VLOOKUP(F39,$P$1:$Q$4,2,0),F39) | P39: =IF(C39="",1,COUNTIFS($C$9:$C$1499,C39,$H$9:$H$1499,H39)) -> 1
A40: אשראי-1 | B40: 03/01/2026 | C40: מקדונלדס APPLE/GOOGLE PAY | D40: 15 | E40: הוצאה | F40: =IFERROR(VLOOKUP(C40,$C$9:H39,4,FALSE),"") | G40: פנאי, בילוי ותחביבים | H40: מסעדה ואוכל בחוץ | J40: 15 | K40: ₪ | L40: 7721 | N40: =IF(OR(F40=$P$1,F40="",F40=0),D40/$B$2,IF(OR(F40=$P$2,F40=$P$3,F40=$P$4),D40/(O40*P40),D40/O40)) -> #DIV/0! | O40: =IFERROR(VLOOKUP(F40,$P$1:$Q$4,2,0),F40) | P40: =IF(C40="",1,COUNTIFS($C$9:$C$1499,C40,$H$9:$H$1499,H40)) -> 1
...

Sheet שלב ג - תוצאות השיקוף
A2: סה"כ הוצאות | B2: =SUM(B4,B25,B46,B67,B88,B109,B130,B151,B172,B193,B214,B235,B256,B277,B298,B319) -> 0 | D2: סה"כ הכנסות | E2: =SUM(E4,E25,E46) -> 0 | G2: הפרש | H2: =E2-B2 -> 0
A4: ='רשימת הסעיפים'!A1 -> מזון ופארמה | B4: =SUM(B5:B24) -> 0 | D4: ='רשימת הסעיפים'!Q1 -> שכר | E4: =SUM(E5:E24) -> 0
A5: ='רשימת הסעיפים'!A2 -> מזון | B5: =IF(A5<>0,SUMIF('שלב ב - סיווג תנועות'!$H$9:$H$1499,A5,'שלב ב - סיווג תנועות'!$N$9:$N$1499),0) -> 0 | D5: ='רשימת הסעיפים'!Q2 -> שכר עבודה 1 | E5: =IF(D5<>0,SUMIF('שלב ב - סיווג תנועות'!$H$9:$H$1499,D5,'שלב ב - סיווג תנועות'!$N$9:$N$1499),0) -> 0
A6: ='רשימת הסעיפים'!A3 -> פארמה וטואלטיקה | B6: =IF(A6<>0,SUMIF('שלב ב - סיווג תנועות'!$H$9:$H$1499,A6,'שלב ב - סיווג תנועות'!$N$9:$N$1499),0) -> 0 | D6: ='רשימת הסעיפים'!Q3 -> שכר עבודה 2 | E6: =IF(D6<>0,SUMIF('שלב ב - סיווג תנועות'!$H$9:$H$1499,D6,'שלב ב - סיווג תנועות'!$N$9:$N$1499),0) -> 0
A7: ='רשימת הסעיפים'!A4 -> בר מים | B7: =IF(A7<>0,SUMIF('שלב ב - סיווג תנועות'!$H$9:$H$1499,A7,'שלב ב - סיווג תנועות'!$N$9:$N$1499),0) -> 0 | D7: ='רשימת הסעיפים'!Q4 -> שכר עבודה 3 | E7: =IF(D7<>0,SUMIF('שלב ב - סיווג תנועות'!$H$9:$H$1499,D7,'שלב ב - סיווג תנועות'!$N$9:$N$1499),0) -> 0
A8: ='רשימת הסעיפים'!A5 -> אוכל מוכן / בעבודה | B8: =IF(A8<>0,SUMIF('שלב ב - סיווג תנועות'!$H$9:$H$1499,A8,'שלב ב - סיווג תנועות'!$N$9:$N$1499),0) -> 0 | D8: ='רשימת הסעיפים'!Q5 -> שכר עבודה 4 | E8: =IF(D8<>0,SUMIF('שלב ב - סיווג תנועות'!$H$9:$H$1499,D8,'שלב ב - סיווג תנועות'!$N$9:$N$1499),0) -> 0
A9: ='רשימת הסעיפים'!A6 -> עישון | B9: =IF(A9<>0,SUMIF('שלב ב - סיווג תנועות'!$H$9:$H$1499,A9,'שלב ב - סיווג תנועות'!$N$9:$N$1499),0) -> 0 | D9: ='רשימת הסעיפים'!Q6 -> שכר - כללי | E9: =IF(D9<>0,SUMIF('שלב ב - סיווג תנועות'!$H$9:$H$1499,D9,'שלב ב - סיווג תנועות'!$N$9:$N$1499),0) -> 0
A10: ='רשימת הסעיפים'!A7 -> מזון ופארמה - כללי | B10: =IF(A10<>0,SUMIF('שלב ב - סיווג תנועות'!$H$9:$H$1499,A10,'שלב ב - סיווג תנועות'!$N$9:$N$1499),0) -> 0 | D10: ='רשימת הסעיפים'!Q7 -> 0 | E10: =IF(D10<>0,SUMIF('שלב ב - סיווג תנועות'!$H$9:$H$1499,D10,'שלב ב - סיווג תנועות'!$N$9:$N$1499),0) -> 0
A11: ='רשימת הסעיפים'!A8 -> 0 | B11: =IF(A11<>0,SUMIF('שלב ב - סיווג תנועות'!$H$9:$H$1499,A11,'שלב ב - סיווג תנועות'!$N$9:$N$1499),0) -> 0 | D11: ='רשימת הסעיפים'!Q8 -> 0 | E11: =IF(D11<>0,SUMIF('שלב ב - סיווג תנועות'!$H$9:$H$1499,D11,'שלב ב - סיווג תנועות'!$N$9:$N$1499),0) -> 0
A12: ='רשימת הסעיפים'!A9 -> 0 | B12: =IF(A12<>0,SUMIF('שלב ב - סיווג תנועות'!$H$9:$H$1499,A12,'שלב ב - סיווג תנועות'!$N$9:$N$1499),0) -> 0 | D12: ='רשימת הסעיפים'!Q9 -> 0 | E12: =IF(D12<>0,SUMIF('שלב ב - סיווג תנועות'!$H$9:$H$1499,D12,'שלב ב - סיווג תנועות'!$N$9:$N$1499),0) -> 0
A13: ='רשימת הסעיפים'!A10 -> 0 | B13: =IF(A13<>0,SUMIF('שלב ב - סיווג תנועות'!$H$9:$H$1499,A13,'שלב ב - סיווג תנועות'!$N$9:$N$1499),0) -> 0 | D13: ='רשימת הסעיפים'!Q10 -> 0 | E13: =IF(D13<>0,SUMIF('שלב ב - סיווג תנועות'!$H$9:$H$1499,D13,'שלב ב - סיווג תנועות'!$N$9:$N$1499),0) -> 0
A14: ='רשימת הסעיפים'!A11 -> 0 | B14: =IF(A14<>0,SUMIF('שלב ב - סיווג תנועות'!$H$9:$H$1499,A14,'שלב ב - סיווג תנועות'!$N$9:$N$1499),0) -> 0 | D14: ='רשימת הסעיפים'!Q11 -> 0 | E14: =IF(D14<>0,SUMIF('שלב ב - סיווג תנועות'!$H$9:$H$1499,D14,'שלב ב - סיווג תנועות'!$N$9:$N$1499),0) -> 0
A15: ='רשימת הסעיפים'!A12 -> 0 | B15: =IF(A15<>0,SUMIF('שלב ב - סיווג תנועות'!$H$9:$H$1499,A15,'שלב ב - סיווג תנועות'!$N$9:$N$1499),0) -> 0 | D15: ='רשימת הסעיפים'!Q12 -> 0 | E15: =IF(D15<>0,SUMIF('שלב ב - סיווג תנועות'!$H$9:$H$1499,D15,'שלב ב - סיווג תנועות'!$N$9:$N$1499),0) -> 0
A16: ='רשימת הסעיפים'!A13 -> 0 | B16: =IF(A16<>0,SUMIF('שלב ב - סיווג תנועות'!$H$9:$H$1499,A16,'שלב ב - סיווג תנועות'!$N$9:$N$1499),0) -> 0 | D16: ='רשימת הסעיפים'!Q13 -> 0 | E16: =IF(D16<>0,SUMIF('שלב ב - סיווג תנועות'!$H$9:$H$1499,D16,'שלב ב - סיווג תנועות'!$N$9:$N$1499),0) -> 0
... A24: ='רשימת הסעיפים'!A21 -> 0 | B24: =IF(A24<>0,SUMIF('שלב ב - סיווג תנועות'!$H$9:$H$1499,A24,'שלב ב - סיווג תנועות'!$N$9:$N$1499),0) -> 0 | D24: ='רשימת הסעיפים'!Q21 -> 0 | E24: =IF(D24<>0,SUMIF('שלב ב - סיווג תנועות'!$H$9:$H$1499,D24,'שלב ב - סיווג תנועות'!$N$9:$N$1499),0) -> 0
A25: ='רשימת הסעיפים'!B1 -> פנאי, בילוי ותחביבים | B25: =SUM(B26:B45) -> 0 | D25: ='רשימת הסעיפים'!R1 -> קצבאות | E25: =SUM(E26:E45) -> 0
A26: ='רשימת הסעיפים'!B2 -> מסעדה ואוכל בחוץ | B26: =IF(A26<>0,SUMIF('שלב ב - סיווג תנועות'!$H$9:$H$1499,A26,'שלב ב - סיווג תנועות'!$N$9:$N$1499),0) -> 0 | D26: ='רשימת הסעיפים'!R2 -> קצבת ילדים | E26: =IF(D26<>0,SUMIF('שלב ב - סיווג תנועות'!$H$9:$H$1499,D26,'שלב ב - סיווג תנועות'!$N$9:$N$1499),0) -> 0
A27: ='רשימת הסעיפים'!B3 -> ספורט | B27: =IF(A27<>0,SUMIF('שלב ב - סיווג תנועות'!$H$9:$H$1499,A27,'שלב ב - סיווג תנועות'!$N$9:$N$1499),0) -> 0 | D27: ='רשימת הסעיפים'!R3 -> קצבת נכות | E27: =IF(D27<>0,SUMIF('שלב ב - סיווג תנועות'!$H$9:$H$1499,D27,'שלב ב - סיווג תנועות'!$N$9:$N$1499),0) -> 0
A28: ='רשימת הסעיפים'!B4 -> חופשות | B28: =IF(A28<>0,SUMIF('שלב ב - סיווג תנועות'!$H$9:$H$1499,A28,'שלב ב - סיווג תנועות'!$N$9:$N$1499),0) -> 0 | D28: ='רשימת הסעיפים'!R4 -> סיוע בשכר דירה | E28: =IF(D28<>0,SUMIF('שלב ב - סיווג תנועות'!$H$9:$H$1499,D28,'שלב ב - סיווג תנועות'!$N$9:$N$1499),0) -> 0
A29: ='רשימת הסעיפים'!B5 -> בילויים ומופעים | B29: =IF(A29<>0,SUMIF('שלב ב - סיווג תנועות'!$H$9:$H$1499,A29,'שלב ב - סיווג תנועות'!$N$9:$N$1499),0) -> 0 | D29: ='רשימת הסעיפים'!R5 -> קצבת זיקנה | E29: =IF(D29<>0,SUMIF('שלב ב - סיווג תנועות'!$H$9:$H$1499,D29,'שלב ב - סיווג תנועות'!$N$9:$N$1499),0) -> 0
A30: ='רשימת הסעיפים'!B6 -> חיות מחמד | B30: =IF(A30<>0,SUMIF('שלב ב - סיווג תנועות'!$H$9:$H$1499,A30,'שלב ב - סיווג תנועות'!$N$9:$N$1499),0) -> 0 | D30: ='רשימת הסעיפים'!R6 -> קצבאות - כללי | E30: =IF(D30<>0,SUMIF('שלב ב - סיווג תנועות'!$H$9:$H$1499,D30,'שלב ב - סיווג תנועות'!$N$9:$N$1499),0) -> 0
A31: ='רשימת הסעיפים'!B7 -> חוגי מבוגרים | B31: =IF(A31<>0,SUMIF('שלב ב - סיווג תנועות'!$H$9:$H$1499,A31,'שלב ב - סיווג תנועות'!$N$9:$N$1499),0) -> 0 | D31: ='רשימת הסעיפים'!R7 -> 0 | E31: =IF(D31<>0,SUMIF('שלב ב - סיווג תנועות'!$H$9:$H$1499,D31,'שלב ב - סיווג תנועות'!$N$9:$N$1499),0) -> 0
A32: ='רשימת הסעיפים'!B8 -> בייביסיטר | B32: =IF(A32<>0,SUMIF('שלב ב - סיווג תנועות'!$H$9:$H$1499,A32,'שלב ב - סיווג תנועות'!$N$9:$N$1499),0) -> 0 | D32: ='רשימת הסעיפים'!R8 -> 0 | E32: =IF(D32<>0,SUMIF('שלב ב - סיווג תנועות'!$H$9:$H$1499,D32,'שלב ב - סיווג תנועות'!$N$9:$N$1499),0) -> 0
A33: ='רשימת הסעיפים'!B9 -> הגרלות | B33: =IF(A33<>0,SUMIF('שלב ב - סיווג תנועות'!$H$9:$H$1499,A33,'שלב ב - סיווג תנועות'!$N$9:$N$1499),0) -> 0 | D33: ='רשימת הסעיפים'!R9 -> 0 | E33: =IF(D33<>0,SUMIF('שלב ב - סיווג תנועות'!$H$9:$H$1499,D33,'שלב ב - סיווג תנועות'!$N$9:$N$1499),0) -> 0
A34: ='רשימת הסעיפים'!B10 -> פנאי - כללי | B34: =IF(A34<>0,SUMIF('שלב ב - סיווג תנועות'!$H$9:$H$1499,A34,'שלב ב - סיווג תנועות'!$N$9:$N$1499),0) -> 0 | D34: ='רשימת הסעיפים'!R10 -> 0 | E34: =IF(D34<>0,SUMIF('שלב ב - סיווג תנועות'!$H$9:$H$1499,D34,'שלב ב - סיווג תנועות'!$N$9:$N$1499),0) -> 0
A35: ='רשימת הסעיפים'!B11 -> 0 | B35: =IF(A35<>0,SUMIF('שלב ב - סיווג תנועות'!$H$9:$H$1499,A35,'שלב ב - סיווג תנועות'!$N$9:$N$1499),0) -> 0 | D35: ='רשימת הסעיפים'!R11 -> 0 | E35: =IF(D35<>0,SUMIF('שלב ב - סיווג תנועות'!$H$9:$H$1499,D35,'שלב ב - סיווג תנועות'!$N$9:$N$1499),0) -> 0
A36: ='רשימת הסעיפים'!B12 -> 0 | B36: =IF(A36<>0,SUMIF('שלב ב - סיווג תנועות'!$H$9:$H$1499,A36,'שלב ב - סיווג תנועות'!$N$9:$N$1499),0) -> 0 | D36: ='רשימת הסעיפים'!R12 -> 0 | E36: =IF(D36<>0,SUMIF('שלב ב - סיווג תנועות'!$H$9:$H$1499,D36,'שלב ב - סיווג תנועות'!$N$9:$N$1499),0) -> 0
A37: ='רשימת הסעיפים'!B13 -> 0 | B37: =IF(A37<>0,SUMIF('שלב ב - סיווג תנועות'!$H$9:$H$1499,A37,'שלב ב - סיווג תנועות'!$N$9:$N$1499),0) -> 0 | D37: ='רשימת הסעיפים'!R13 -> 0 | E37: =IF(D37<>0,SUMIF('שלב ב - סיווג תנועות'!$H$9:$H$1499,D37,'שלב ב - סיווג תנועות'!$N$9:$N$1499),0) -> 0
... A45: ='רשימת הסעיפים'!B21 -> 0 | B45: =IF(A45<>0,SUMIF('שלב ב - סיווג תנועות'!$H$9:$H$1499,A45,'שלב ב - סיווג תנועות'!$N$9:$N$1499),0) -> 0 | D45: ='רשימת הסעיפים'!R21 -> 0 | E45: =IF(D45<>0,SUMIF('שלב ב - סיווג תנועות'!$H$9:$H$1499,D45,'שלב ב - סיווג תנועות'!$N$9:$N$1499),0) -> 0
A46: ='רשימת הסעיפים'!C1 -> ביגוד והנעלה | B46: =SUM(B47:B66) -> 0 | D46: ='רשימת הסעיפים'!S1 -> הכנסות שונות | E46: =SUM(E47:E66) -> 0
A47: ='רשימת הסעיפים'!C2 -> ביגוד הורים | B47: =IF(A47<>0,SUMIF('שלב ב - סיווג תנועות'!$H$9:$H$1499,A47,'שלב ב - סיווג תנועות'!$N$9:$N$1499),0) -> 0 | D47: ='רשימת הסעיפים'!S2 -> קבלת מזונות | E47: =IF(D47<>0,SUMIF('שלב ב - סיווג תנועות'!$H$9:$H$1499,D47,'שלב ב - סיווג תנועות'!$N$9:$N$1499),0) -> 0
A48: ='רשימת הסעיפים'!C3 -> ביגוד ילדים | B48: =IF(A48<>0,SUMIF('שלב ב - סיווג תנועות'!$H$9:$H$1499,A48,'שלב ב - סיווג תנועות'!$N$9:$N$1499),0) -> 0 | D48: ='רשימת הסעיפים'!S3 -> הכנסה מנכס | E48: =IF(D48<>0,SUMIF('שלב ב - סיווג תנועות'!$H$9:$H$1499,D48,'שלב ב - סיווג תנועות'!$N$9:$N$1499),0) -> 0
A49: ='רשימת הסעיפים'!C4 -> נעליים | B49: =IF(A49<>0,SUMIF('שלב ב - סיווג תנועות'!$H$9:$H$1499,A49,'שלב ב - סיווג תנועות'!$N$9:$N$1499),0) -> 0 | D49: ='רשימת הסעיפים'!S4 -> עזרה מההורים | E49: =IF(D49<>0,SUMIF('שלב ב - סיווג תנועות'!$H$9:$H$1499,D49,'שלב ב - סיווג תנועות'!$N$9:$N$1499),0) -> 0
A50: ='רשימת הסעיפים'!C5 -> ביגוד והנעלה - כללי | B50: =IF(A50<>0,SUMIF('שלב ב - סיווג תנועות'!$H$9:$H$1499,A50,'שלב ב - סיווג תנועות'!$N$9:$N$1499),0) -> 0 | D50: ='רשימת הסעיפים'!S5 -> הכנסות שונות - כללי | E50: =IF(D50<>0,SUMIF('שלב ב - סיווג תנועות'!$H$9:$H$1499,D50,'שלב ב - סיווג תנועות'!$N$9:$N$1499),0) -> 0
A51: ='רשימת הסעיפים'!C6 -> 0 | B51: =IF(A51<>0,SUMIF('שלב ב - סיווג תנועות'!$H$9:$H$1499,A51,'שלב ב - סיווג תנועות'!$N$9:$N$1499),0) -> 0 | D51: ='רשימת הסעיפים'!S6 -> 0 | E51: =IF(D51<>0,SUMIF('שלב ב - סיווג תנועות'!$H$9:$H$1499,D51,'שלב ב - סיווג תנועות'!$N$9:$N$1499),0) -> 0
A52: ='רשימת הסעיפים'!C7 -> 0 | B52: =IF(A52<>0,SUMIF('שלב ב - סיווג תנועות'!$H$9:$H$1499,A52,'שלב ב - סיווג תנועות'!$N$9:$N$1499),0) -> 0 | D52: ='רשימת הסעיפים'!S7 -> 0 | E52: =IF(D52<>0,SUMIF('שלב ב - סיווג תנועות'!$H$9:$H$1499,D52,'שלב ב - סיווג תנועות'!$N$9:$N$1499),0) -> 0
A53: ='רשימת הסעיפים'!C8 -> 0 | B53: =IF(A53<>0,SUMIF('שלב ב - סיווג תנועות'!$H$9:$H$1499,A53,'שלב ב - סיווג תנועות'!$N$9:$N$1499),0) -> 0 | D53: ='רשימת הסעיפים'!S8 -> 0 | E53: =IF(D53<>0,SUMIF('שלב ב - סיווג תנועות'!$H$9:$H$1499,D53,'שלב ב - סיווג תנועות'!$N$9:$N$1499),0) -> 0
A54: ='רשימת הסעיפים'!C9 -> 0 | B54: =IF(A54<>0,SUMIF('שלב ב - סיווג תנועות'!$H$9:$H$1499,A54,'שלב ב - סיווג תנועות'!$N$9:$N$1499),0) -> 0 | D54: ='רשימת הסעיפים'!S9 -> 0 | E54: =IF(D54<>0,SUMIF('שלב ב - סיווג תנועות'!$H$9:$H$1499,D54,'שלב ב - סיווג תנועות'!$N$9:$N$1499),0) -> 0
A55: ='רשימת הסעיפים'!C10 -> 0 | B55: =IF(A55<>0,SUMIF('שלב ב - סיווג תנועות'!$H$9:$H$1499,A55,'שלב ב - סיווג תנועות'!$N$9:$N$1499),0) -> 0 | D55: ='רשימת הסעיפים'!S10 -> 0 | E55: =IF(D55<>0,SUMIF('שלב ב - סיווג תנועות'!$H$9:$H$1499,D55,'שלב ב - סיווג תנועות'!$N$9:$N$1499),0) -> 0
A56: ='רשימת הסעיפים'!C11 -> 0 | B56: =IF(A56<>0,SUMIF('שלב ב - סיווג תנועות'!$H$9:$H$1499,A56,'שלב ב - סיווג תנועות'!$N$9:$N$1499),0) -> 0 | D56: ='רשימת הסעיפים'!S11 -> 0 | E56: =IF(D56<>0,SUMIF('שלב ב - סיווג תנועות'!$H$9:$H$1499,D56,'שלב ב - סיווג תנועות'!$N$9:$N$1499),0) -> 0
...

Sheet חובות
A2: חובות
A3: שם מזהה | B3: קרן התחלתית | C3: יתרה | D3: ריבית | E3: מספר תשלומים מקורי | F3: מספר תשלומים שנותרו | G3: החזר חודשי | H3: בסיס ריבית | I3: לוח | J3: מספר תשלומים שנפרעו | K3: מועד תשלום | L3: מועד תשלום ראשון | M3: מועד תשלום אחרון | N3: מועד מידע | O3: יתרה לסילוק | P3: עלות פירעון מוקדם | Q3: הערות
A4: מסגרת אשראי בחשבון הבנק (מינוס)

Sheet חסכונות
A2: חסכונות | D2: ממוצע חודשי מהשיקוף לסעיף 'הוראות קבע לחיסכון': | E2: =#REF! -> #REF!
A3: סוג | B3: גוף | C3: סך | D3: מסלול השקעה | E3: מזהה / ח-ן | F3: תאריך מידע | G3: חוסך | H3: תאריך נזילות | I3: ד"נ | J3: מעמד | K3: מעסיק רשום | L3: ביטוחים כלולים | M3: אפשרות להלוואה כנגד החיסכון | N3: הערות

Sheet ביטוחים
A2: ביטוחים | E2: ממוצע חודשי מהשיקוף לסעיף 'ביטוחים (למעט רכב)': | F2: =#REF! -> #REF!
A3: חברה מבטחת | B3: מס' פוליסה | C3: סוג ביטוח | D3: מבוטח | E3: כיסוי | F3: השתתפות עצמית | G3: החרגות | H3: תחילת ביטוח | I3: תום ביטוח | J3: סוג פרמיה | K3: פרמיה שנתית | L3: פרמיה חודשית | M3: סוכן | N3: הערות

Sheet רשימת הסעיפים
A1: מזון ופארמה | B1: פנאי, בילוי ותחביבים | C1: ביגוד והנעלה | D1: תכולת בית | E1: אחזקת בית | F1: טיפוח | G1: חינוך | H1: אירועים, תרומות, צרכי דת | I1: בריאות | J1: תחבורה | K1: משפחה | L1: תקשורת | M1: דיור | N1: התחייבויות | O1: נכסים | P1: פיננסים | Q1: שכר | R1: קצבאות | S1: הכנסות שונות
A2: מזון | B2: מסעדה ואוכל בחוץ | C2: ביגוד הורים | D2: ריהוט | E2: חשמל | F2: מספרה | G2: בית ספר | H2: חגים וצרכי דת | I2: קופ"ח תשלום קבוע | J2: דלק | K2: ארועי שמחות במשפחה | L2: טלפון נייד ונייח | M2: משכנתה | N2: החזר חובות חודשי (למעט משכנתה) - כללי | O2: הפקדות לחסכונות - כללי | P2: עמלות | Q2: שכר עבודה 1 | R2: קצבת ילדים | S2: קבלת מזונות | AA2: כל סעיפי הוצאה | AB2: כל סעיפי הכנסה | AC2: כל סעיפי הוצאה ללא רווחים | AD2: כל סעיפי הכנסה ללא רווחים
A3: פארמה וטואלטיקה | B3: ספורט | C3: ביגוד ילדים | D3: מוצרי חשמל ואלקטרוניקה | E3: מים וביוב | F3: קוסמטיקה | G3: מסגרות צהריים | H3: אירוע בעבודה / לחברים | I3: ביטוח רפואי נוסף | J3: חניה | K3: דמי כיס | L3: טלויזיה ואינטרנט (ספק ותשתית) | M3: שכר דירה | N3: ריביות משיכת יתר | P3: ביטוח חיים | Q3: שכר עבודה 2 | R3: קצבת נכות | S3: הכנסה מנכס
A4: בר מים | B4: חופשות | C4: נעליים | D4: משחקים, צעצועים וספרים | E4: גז | F4: טיפוח - כללי | G4: מסגרות יום | H4: תרומות | I4: טיפולים פרטיים | J4: כבישי אגרה | K4: עזרה למשפחה | L4: שירותי תוכן | M4: מיסי ישוב / ועד בית | P4: ביטוח לאומי (למי שלא עובד) | Q4: שכר עבודה 3 | R4: סיוע בשכר דירה | S4: עזרה מההורים | AA4: =IF(A2="","",A2) -> מזון | AB4: =IF(Q2="","",Q2) -> שכר עבודה 1 | AC4: =IFERROR(INDEX(BlanksRangeExp,SMALL((IF(LEN(BlanksRangeExp),ROW(INDIRECT("1:"&ROWS(BlanksRangeExp))))),ROW(A1)),1),"") -> מזון | AD4: {=IFERROR(INDEX(BlanksRangeInc,SMALL((IF(LEN(BlanksRangeInc),ROW(INDIRECT("1:"&ROWS(BlanksRangeInc))))),ROW(A1)),1),"")} -> שכר עבודה 1 | AG4: =טבלה4[[#Headers],[מזון ופארמה]] -> מזון ופארמה | AH4: ExpFood
A5: אוכל מוכן / בעבודה | B5: בילויים ומופעים | C5: ביגוד והנעלה - כללי | D5: כלי בית | E5: ניקיון | G5: צהרון / מטפלת | I5: תרופות | J5: ביטוח רכב | K5: תשלום מזונות | L5: תקשורת - כללי | M5: ארנונה | P5: פיננסים - כללי | Q5: שכר עבודה 4 | R5: קצבת זיקנה | S5: הכנסות שונות - כללי | AA5: =IF(A3="","",A3) -> פארמה וטואלטיקה | AB5: =IF(Q3="","",Q3) -> שכר עבודה 2 | AC5: {=IFERROR(INDEX(BlanksRangeExp,SMALL((IF(LEN(BlanksRangeExp),ROW(INDIRECT("1:"&ROWS(BlanksRangeExp))))),ROW(A2)),1),"")} -> פארמה וטואלטיקה | AD5: {=IFERROR(INDEX(BlanksRangeInc,SMALL((IF(LEN(BlanksRangeInc),ROW(INDIRECT("1:"&ROWS(BlanksRangeInc))))),ROW(A2)),1),"")} -> שכר עבודה 2 | AG5: =טבלה7[[#Headers],[פנאי, בילוי ותחביבים]] -> פנאי, בילוי ותחביבים | AH5: ExpHobby
A6: עישון | B6: חיות מחמד | D6: תכולת בית - כללי | E6: תיקונים בבית / במכשירים | G6: הסעות | I6: טיפולי שיניים / אורטודנט | J6: תחזוקת רכב | K6: משפחה - כללי | M6: ביטוח נכס ותכולה | Q6: שכר - כללי | R6: קצבאות - כללי | AA6: =IF(A4="","",A4) -> בר מים | AB6: =IF(Q4="","",Q4) -> שכר עבודה 3 | AC6: {=IFERROR(INDEX(BlanksRangeExp,SMALL((IF(LEN(BlanksRangeExp),ROW(INDIRECT("1:"&ROWS(BlanksRangeExp))))),ROW(A3)),1),"")} -> בר מים | AD6: {=IFERROR(INDEX(BlanksRangeInc,SMALL((IF(LEN(BlanksRangeInc),ROW(INDIRECT("1:"&ROWS(BlanksRangeInc))))),ROW(A3)),1),"")} -> שכר עבודה 3 | AG6: =טבלה8[[#Headers],[ביגוד והנעלה]] -> ביגוד והנעלה | AH6: ExpCloth
A7: מזון ופארמה - כללי | B7: חוגי מבוגרים | E7: גינה | G7: שיעור פרטי | I7: אופטיקה | J7: תחבורה ציבורית | M7: דיור - כללי | AA7: =IF(A5="","",A5) -> אוכל מוכן / בעבודה | AB7: =IF(Q5="","",Q5) -> שכר עבודה 4 | AC7: {=IFERROR(INDEX(BlanksRangeExp,SMALL((IF(LEN(BlanksRangeExp),ROW(INDIRECT("1:"&ROWS(BlanksRangeExp))))),ROW(A4)),1),"")} -> אוכל מוכן / בעבודה | AD7: {=IFERROR(INDEX(BlanksRangeInc,SMALL((IF(LEN(BlanksRangeInc),ROW(INDIRECT("1:"&ROWS(BlanksRangeInc))))),ROW(A4)),1),"")} -> שכר עבודה 4 | AG7: =טבלה9[[#Headers],[תכולת בית]] -> תכולת בית | AH7: ExpHomeCont
B8: בייביסיטר | E8: אחזקת בית - כללי | G8: מסגרות קיץ | I8: בריאות - כללי | J8: רישוי רכב | AA8: =IF(A6="","",A6) -> עישון | AB8: =IF(Q6="","",Q6) -> שכר - כללי | AC8: {=IFERROR(INDEX(BlanksRangeExp,SMALL((IF(LEN(BlanksRangeExp),ROW(INDIRECT("1:"&ROWS(BlanksRangeExp))))),ROW(A5)),1),"")} -> עישון | AD8: {=IFERROR(INDEX(BlanksRangeInc,SMALL((IF(LEN(BlanksRangeInc),ROW(INDIRECT("1:"&ROWS(BlanksRangeInc))))),ROW(A5)),1),"")} -> שכר - כללי | AG8: =טבלה10[[#Headers],[אחזקת בית]] -> אחזקת בית | AH8: ExpHome
B9: הגרלות | G9: חוגים ותנועת נוער | J9: תחבורה שיתופית | AA9: =IF(A7="","",A7) -> מזון ופארמה - כללי | AB9: =IF(Q7="","",Q7) | AC9: {=IFERROR(INDEX(BlanksRangeExp,SMALL((IF(LEN(BlanksRangeExp),ROW(INDIRECT("1:"&ROWS(BlanksRangeExp))))),ROW(A6)),1),"")} -> מזון ופארמה - כללי | AD9: {=IFERROR(INDEX(BlanksRangeInc,SMALL((IF(LEN(BlanksRangeInc),ROW(INDIRECT("1:"&ROWS(BlanksRangeInc))))),ROW(A6)),1),"")} -> קצבת ילדים | AG9: =טבלה11[[#Headers],[טיפוח]] -> טיפוח | AH9: ExpCare
B10: פנאי - כללי | G10: לימודים והשתלמות לבוגרים | J10: ליסינג | AA10: =IF(A8="","",A8) | AB10: =IF(Q8="","",Q8) | AC10: {=IFERROR(INDEX(BlanksRangeExp,SMALL((IF(LEN(BlanksRangeExp),ROW(INDIRECT("1:"&ROWS(BlanksRangeExp))))),ROW(A7)),1),"")} -> מסעדה ואוכל בחוץ | AD10: {=IFERROR(INDEX(BlanksRangeInc,SMALL((IF(LEN(BlanksRangeInc),ROW(INDIRECT("1:"&ROWS(BlanksRangeInc))))),ROW(A7)),1),"")} -> קצבת נכות | AG10: =טבלה12[[#Headers],[חינוך]] -> חינוך | AH10: ExpEdu
G11: חינוך - כללי | J11: תחבורה - כללי | AA11: =IF(A9="","",A9) | AB11: =IF(Q9="","",Q9) | AC11: {=IFERROR(INDEX(BlanksRangeExp,SMALL((IF(LEN(BlanksRangeExp),ROW(INDIRECT("1:"&ROWS(BlanksRangeExp))))),ROW(A8)),1),"")} -> ספורט | AD11: {=IFERROR(INDEX(BlanksRangeInc,SMALL((IF(LEN(BlanksRangeInc),ROW(INDIRECT("1:"&ROWS(BlanksRangeInc))))),ROW(A8)),1),"")} -> סיוע בשכר דירה | AG11: =טבלה13[[#Headers],[אירועים, תרומות, צרכי דת]] -> אירועים, תרומות, צרכי דת | AH11: ExpEvents
AA12: =IF(A10="","",A10) | AB12: =IF(Q10="","",Q10) | AC12: {=IFERROR(INDEX(BlanksRangeExp,SMALL((IF(LEN(BlanksRangeExp),ROW(INDIRECT("1:"&ROWS(BlanksRangeExp))))),ROW(A9)),1),"")} -> חופשות | AD12: {=IFERROR(INDEX(BlanksRangeInc,SMALL((IF(LEN(BlanksRangeInc),ROW(INDIRECT("1:"&ROWS(BlanksRangeInc))))),ROW(A9)),1),"")} -> קצבת זיקנה | AG12: =טבלה14[[#Headers],[בריאות]] -> בריאות | AH12: ExpHealth
AA13: =IF(A11="","",A11) | AB13: =IF(Q11="","",Q11) | AC13: {=IFERROR(INDEX(BlanksRangeExp,SMALL((IF(LEN(BlanksRangeExp),ROW(INDIRECT("1:"&ROWS(BlanksRangeExp))))),ROW(A10)),1),"")} -> בילויים ומופעים | AD13: {=IFERROR(INDEX(BlanksRangeInc,SMALL((IF(LEN(BlanksRangeInc),ROW(INDIRECT("1:"&ROWS(BlanksRangeInc))))),ROW(A10)),1),"")} -> קצבאות - כללי | AG13: =טבלה15[[#Headers],[תחבורה]] -> תחבורה | AH13: ExpTransp
AA14: =IF(A12="","",A12) | AB14: =IF(Q12="","",Q12) | AC14: {=IFERROR(INDEX(BlanksRangeExp,SMALL((IF(LEN(BlanksRangeExp),ROW(INDIRECT("1:"&ROWS(BlanksRangeExp))))),ROW(A11)),1),"")} -> חיות מחמד | AD14: {=IFERROR(INDEX(BlanksRangeInc,SMALL((IF(LEN(BlanksRangeInc),ROW(INDIRECT("1:"&ROWS(BlanksRangeInc))))),ROW(A11)),1),"")} -> קבלת מזונות | AG14: =טבלה16[[#Headers],[משפחה]] -> משפחה | AH14: ExpFamily
AA15: =IF(A13="","",A13) | AB15: =IF(Q13="","",Q13) | AC15: {=IFERROR(INDEX(BlanksRangeExp,SMALL((IF(LEN(BlanksRangeExp),ROW(INDIRECT("1:"&ROWS(BlanksRangeExp))))),ROW(A12)),1),"")} -> חוגי מבוגרים | AD15: {=IFERROR(INDEX(BlanksRangeInc,SMALL((IF(LEN(BlanksRangeInc),ROW(INDIRECT("1:"&ROWS(BlanksRangeInc))))),ROW(A12)),1),"")} -> הכנסה מנכס | AG15: =טבלה17[[#Headers],[תקשורת]] -> תקשורת | AH15: ExpCom
AA16: =IF(A14="","",A14) | AB16: =IF(Q14="","",Q14) | AC16: {=IFERROR(INDEX(BlanksRangeExp,SMALL((IF(LEN(BlanksRangeExp),ROW(INDIRECT("1:"&ROWS(BlanksRangeExp))))),ROW(A13)),1),"")} -> בייביסיטר | AD16: {=IFERROR(INDEX(BlanksRangeInc,SMALL((IF(LEN(BlanksRangeInc),ROW(INDIRECT("1:"&ROWS(BlanksRangeInc))))),ROW(A13)),1),"")} -> עזרה מההורים | AG16: =טבלה18[[#Headers],[דיור]] -> דיור | AH16: ExpHousing
AA17: =IF(A15="","",A15) | AB17: =IF(Q15="","",Q15) | AC17: {=IFERROR(INDEX(BlanksRangeExp,SMALL((IF(LEN(BlanksRangeExp),ROW(INDIRECT("1:"&ROWS(BlanksRangeExp))))),ROW(A14)),1),"")} -> הגרלות | AD17: {=IFERROR(INDEX(BlanksRangeInc,SMALL((IF(LEN(BlanksRangeInc),ROW(INDIRECT("1:"&ROWS(BlanksRangeInc))))),ROW(A14)),1),"")} -> הכנסות שונות - כללי | AG17: =טבלה19[[#Headers],[התחייבויות]] -> התחייבויות | AH17: ExpCommit
AA18: =IF(A16="","",A16) | AB18: =IF(Q16="","",Q16) | AC18: {=IFERROR(INDEX(BlanksRangeExp,SMALL((IF(LEN(BlanksRangeExp),ROW(INDIRECT("1:"&ROWS(BlanksRangeExp))))),ROW(A15)),1),"")} -> פנאי - כללי | AD18: {=IFERROR(INDEX(BlanksRangeInc,SMALL((IF(LEN(BlanksRangeInc),ROW(INDIRECT("1:"&ROWS(BlanksRangeInc))))),ROW(A15)),1),"")} | AG18: =טבלה20[[#Headers],[נכסים]] -> נכסים | AH18: ExpProp
AA19: =IF(A17="","",A17) | AB19: =IF(Q17="","",Q17) | AC19: {=IFERROR(INDEX(BlanksRangeExp,SMALL((IF(LEN(BlanksRangeExp),ROW(INDIRECT("1:"&ROWS(BlanksRangeExp))))),ROW(A16)),1),"")} -> ביגוד הורים | AD19: {=IFERROR(INDEX(BlanksRangeInc,SMALL((IF(LEN(BlanksRangeInc),ROW(INDIRECT("1:"&ROWS(BlanksRangeInc))))),ROW(A16)),1),"")} | AG19: =טבלה21[[#Headers],[פיננסים]] -> פיננסים | AH19: ExpFin
AA20: =IF(A18="","",A18) | AB20: =IF(Q18="","",Q18) | AC20: {=IFERROR(INDEX(BlanksRangeExp,SMALL((IF(LEN(BlanksRangeExp),ROW(INDIRECT("1:"&ROWS(BlanksRangeExp))))),ROW(A17)),1),"")} -> ביגוד ילדים | AD20: {=IFERROR(INDEX(BlanksRangeInc,SMALL((IF(LEN(BlanksRangeInc),ROW(INDIRECT("1:"&ROWS(BlanksRangeInc))))),ROW(A17)),1),"")} | AG20: לא לסיווג
AA21: =IF(A19="","",A19) | AB21: =IF(Q19="","",Q19) | AC21: {=IFERROR(INDEX(BlanksRangeExp,SMALL((IF(LEN(BlanksRangeExp),ROW(INDIRECT("1:"&ROWS(BlanksRangeExp))))),ROW(A18)),1),"")} -> נעליים | AD21: {=IFERROR(INDEX(BlanksRangeInc,SMALL((IF(LEN(BlanksRangeInc),ROW(INDIRECT("1:"&ROWS(BlanksRangeInc))))),ROW(A18)),1),"")} | AG21: =טבלה22[[#Headers],[שכר]] -> שכר | AH21: IncSal
AA22: =IF(A20="","",A20) | AB22: =IF(Q20="","",Q20) | AC22: {=IFERROR(INDEX(BlanksRangeExp,SMALL((IF(LEN(BlanksRangeExp),ROW(INDIRECT("1:"&ROWS(BlanksRangeExp))))),ROW(A19)),1),"")} -> ביגוד והנעלה - כללי | AD22: {=IFERROR(INDEX(BlanksRangeInc,SMALL((IF(LEN(BlanksRangeInc),ROW(INDIRECT("1:"&ROWS(BlanksRangeInc))))),ROW(A19)),1),"")} | AG22: =טבלה23[[#Headers],[קצבאות]] -> קצבאות | AH22: IncAllow
AA23: =IF(A21="","",A21) | AB23: =IF(Q21="","",Q21) | AC23: {=IFERROR(INDEX(BlanksRangeExp,SMALL((IF(LEN(BlanksRangeExp),ROW(INDIRECT("1:"&ROWS(BlanksRangeExp))))),ROW(A20)),1),"")} -> ריהוט | AD23: {=IFERROR(INDEX(BlanksRangeInc,SMALL((IF(LEN(BlanksRangeInc),ROW(INDIRECT("1:"&ROWS(BlanksRangeInc))))),ROW(A20)),1),"")} | AG23: =טבלה24[[#Headers],[הכנסות שונות]] -> הכנסות שונות | AH23: IncMisc
AA24: =IF(B2="","",B2) -> מסעדה ואוכל בחוץ | AB24: =IF(R2="","",R2) -> קצבת ילדים | AC24: {=IFERROR(INDEX(BlanksRangeExp,SMALL((IF(LEN(BlanksRangeExp),ROW(INDIRECT("1:"&ROWS(BlanksRangeExp))))),ROW(A21)),1),"")} -> מוצרי חשמל ואלקטרוניקה | AD24: {=IFERROR(INDEX(BlanksRangeInc,SMALL((IF(LEN(BlanksRangeInc),ROW(INDIRECT("1:"&ROWS(BlanksRangeInc))))),ROW(A21)),1),"")} | AG24: לא לסיווג
AA25: =IF(B3="","",B3) -> ספורט | AB25: =IF(R3="","",R3) -> קצבת נכות | AC25: {=IFERROR(INDEX(BlanksRangeExp,SMALL((IF(LEN(BlanksRangeExp),ROW(INDIRECT("1:"&ROWS(BlanksRangeExp))))),ROW(A22)),1),"")} -> משחקים, צעצועים וספרים | AD25: {=IFERROR(INDEX(BlanksRangeInc,SMALL((IF(LEN(BlanksRangeInc),ROW(INDIRECT("1:"&ROWS(BlanksRangeInc))))),ROW(A22)),1),"")}
AA26: =IF(B4="","",B4) -> חופשות | AB26: =IF(R4="","",R4) -> סיוע בשכר דירה | AC26: {=IFERROR(INDEX(BlanksRangeExp,SMALL((IF(LEN(BlanksRangeExp),ROW(INDIRECT("1:"&ROWS(BlanksRangeExp))))),ROW(A23)),1),"")} -> כלי בית | AD26: {=IFERROR(INDEX(BlanksRangeInc,SMALL((IF(LEN(BlanksRangeInc),ROW(INDIRECT("1:"&ROWS(BlanksRangeInc))))),ROW(A23)),1),"")}
AA27: =IF(B5="","",B5) -> בילויים ומופעים | AB27: =IF(R5="","",R5) -> קצבת זיקנה | AC27: {=IFERROR(INDEX(BlanksRangeExp,SMALL((IF(LEN(BlanksRangeExp),ROW(INDIRECT("1:"&ROWS(BlanksRangeExp))))),ROW(A24)),1),"")} -> תכולת בית - כללי | AD27: {=IFERROR(INDEX(BlanksRangeInc,SMALL((IF(LEN(BlanksRangeInc),ROW(INDIRECT("1:"&ROWS(BlanksRangeInc))))),ROW(A24)),1),"")}
AA28: =IF(B6="","",B6) -> חיות מחמד | AB28: =IF(R6="","",R6) -> קצבאות - כללי | AC28: {=IFERROR(INDEX(BlanksRangeExp,SMALL((IF(LEN(BlanksRangeExp),ROW(INDIRECT("1:"&ROWS(BlanksRangeExp))))),ROW(A25)),1),"")} -> חשמל | AD28: {=IFERROR(INDEX(BlanksRangeInc,SMALL((IF(LEN(BlanksRangeInc),ROW(INDIRECT("1:"&ROWS(BlanksRangeInc))))),ROW(A25)),1),"")}
AA29: =IF(B7="","",B7) -> חוגי מבוגרים | AB29: =IF(R7="","",R7) | AC29: {=IFERROR(INDEX(BlanksRangeExp,SMALL((IF(LEN(BlanksRangeExp),ROW(INDIRECT("1:"&ROWS(BlanksRangeExp))))),ROW(A26)),1),"")} -> מים וביוב | AD29: {=IFERROR(INDEX(BlanksRangeInc,SMALL((IF(LEN(BlanksRangeInc),ROW(INDIRECT("1:"&ROWS(BlanksRangeInc))))),ROW(A26)),1),"")}
AA30: =IF(B8="","",B8) -> בייביסיטר | AB30: =IF(R8="","",R8) | AC30: {=IFERROR(INDEX(BlanksRangeExp,SMALL((IF(LEN(BlanksRangeExp),ROW(INDIRECT("1:"&ROWS(BlanksRangeExp))))),ROW(A27)),1),"")} -> גז | AD30: {=IFERROR(INDEX(BlanksRangeInc,SMALL((IF(LEN(BlanksRangeInc),ROW(INDIRECT("1:"&ROWS(BlanksRangeInc))))),ROW(A27)),1),"")}
AA31: =IF(B9="","",B9) -> הגרלות | AB31: =IF(R9="","",R9) | AC31: {=IFERROR(INDEX(BlanksRangeExp,SMALL((IF(LEN(BlanksRangeExp),ROW(INDIRECT("1:"&ROWS(BlanksRangeExp))))),ROW(A28)),1),"")} -> ניקיון | AD31: {=IFERROR(INDEX(BlanksRangeInc,SMALL((IF(LEN(BlanksRangeInc),ROW(INDIRECT("1:"&ROWS(BlanksRangeInc))))),ROW(A28)),1),"")}
AA32: =IF(B10="","",B10) -> פנאי - כללי | AB32: =IF(R10="","",R10) | AC32: {=IFERROR(INDEX(BlanksRangeExp,SMALL((IF(LEN(BlanksRangeExp),ROW(INDIRECT("1:"&ROWS(BlanksRangeExp))))),ROW(A29)),1),"")} -> תיקונים בבית / במכשירים | AD32: {=IFERROR(INDEX(BlanksRangeInc,SMALL((IF(LEN(BlanksRangeInc),ROW(INDIRECT("1:"&ROWS(BlanksRangeInc))))),ROW(A29)),1),"")}
AA33: =IF(B11="","",B11) | AB33: =IF(R11="","",R11) | AC33: {=IFERROR(INDEX(BlanksRangeExp,SMALL((IF(LEN(BlanksRangeExp),ROW(INDIRECT("1:"&ROWS(BlanksRangeExp))))),ROW(A30)),1),"")} -> גינה | AD33: {=IFERROR(INDEX(BlanksRangeInc,SMALL((IF(LEN(BlanksRangeInc),ROW(INDIRECT("1:"&ROWS(BlanksRangeInc))))),ROW(A30)),1),"")}
AA34: =IF(B12="","",B12) | AB34: =IF(R12="","",R12) | AC34: {=IFERROR(INDEX(BlanksRangeExp,SMALL((IF(LEN(BlanksRangeExp),ROW(INDIRECT("1:"&ROWS(BlanksRangeExp))))),ROW(A31)),1),"")} -> אחזקת בית - כללי | AD34: {=IFERROR(INDEX(BlanksRangeInc,SMALL((IF(LEN(BlanksRangeInc),ROW(INDIRECT("1:"&ROWS(BlanksRangeInc))))),ROW(A31)),1),"")}
AA35: =IF(B13="","",B13) | AB35: =IF(R13="","",R13) | AC35: {=IFERROR(INDEX(BlanksRangeExp,SMALL((IF(LEN(BlanksRangeExp),ROW(INDIRECT("1:"&ROWS(BlanksRangeExp))))),ROW(A32)),1),"")} -> מספרה | AD35: {=IFERROR(INDEX(BlanksRangeInc,SMALL((IF(LEN(BlanksRangeInc),ROW(INDIRECT("1:"&ROWS(BlanksRangeInc))))),ROW(A32)),1),"")}
AA36: =IF(B14="","",B14) | AB36: =IF(R14="","",R14) | AC36: {=IFERROR(INDEX(BlanksRangeExp,SMALL((IF(LEN(BlanksRangeExp),ROW(INDIRECT("1:"&ROWS(BlanksRangeExp))))),ROW(A33)),1),"")} -> קוסמטיקה | AD36: {=IFERROR(INDEX(BlanksRangeInc,SMALL((IF(LEN(BlanksRangeInc),ROW(INDIRECT("1:"&ROWS(BlanksRangeInc))))),ROW(A33)),1),"")}
... AA43: =IF(B21="","",B21) | AB43: =IF(R21="","",R21) | AC43: {=IFERROR(INDEX(BlanksRangeExp,SMALL((IF(LEN(BlanksRangeExp),ROW(INDIRECT("1:"&ROWS(BlanksRangeExp))))),ROW(A40)),1),"")} -> שיעור פרטי | AD43: {=IFERROR(INDEX(BlanksRangeInc,SMALL((IF(LEN(BlanksRangeInc),ROW(INDIRECT("1:"&ROWS(BlanksRangeInc))))),ROW(A40)),1),"")}
AA44: =IF(C2="","",C2) -> ביגוד הורים | AB44: =IF(S2="","",S2) -> קבלת מזונות | AC44: {=IFERROR(INDEX(BlanksRangeExp,SMALL((IF(LEN(BlanksRangeExp),ROW(INDIRECT("1:"&ROWS(BlanksRangeExp))))),ROW(A41)),1),"")} -> מסגרות קיץ | AD44: {=IFERROR(INDEX(BlanksRangeInc,SMALL((IF(LEN(BlanksRangeInc),ROW(INDIRECT("1:"&ROWS(BlanksRangeInc))))),ROW(A41)),1),"")}
AA45: =IF(C3="","",C3) -> ביגוד ילדים | AB45: =IF(S3="","",S3) -> הכנסה מנכס | AC45: {=IFERROR(INDEX(BlanksRangeExp,SMALL((IF(LEN(BlanksRangeExp),ROW(INDIRECT("1:"&ROWS(BlanksRangeExp))))),ROW(A42)),1),"")} -> חוגים ותנועת נוער | AD45: {=IFERROR(INDEX(BlanksRangeInc,SMALL((IF(LEN(BlanksRangeInc),ROW(INDIRECT("1:"&ROWS(BlanksRangeInc))))),ROW(A42)),1),"")}
AA46: =IF(C4="","",C4) -> נעליים | AB46: =IF(S4="","",S4) -> עזרה מההורים | AC46: {=IFERROR(INDEX(BlanksRangeExp,SMALL((IF(LEN(BlanksRangeExp),ROW(INDIRECT("1:"&ROWS(BlanksRangeExp))))),ROW(A43)),1),"")} -> לימודים והשתלמות לבוגרים | AD46: {=IFERROR(INDEX(BlanksRangeInc,SMALL((IF(LEN(BlanksRangeInc),ROW(INDIRECT("1:"&ROWS(BlanksRangeInc))))),ROW(A43)),1),"")}
...

Sheet שמור1 - היסטוריית גירסאות
A1: אין למחוק גיליון זה
B3: 250520 | C3: ראשונית. נשלח לעיצוב ומועמד לתיקוף
B4: 270520 | C4: סעיפים פרטיים בצבע שונה, גיליון רשימת בנקים וחברות אשראי, הגנת חוברת עבודה,
C5: דיוק בשמות הבנקים וחברות האשראי
C6: התייחסות למטבע זר בגיליון הדרכה
C7: תיקון פרטים לפורמט דף כרטיס מקס
C8: ביטול הגנה מכותרות העמודות לטובת oneDrive ועדכון הכיתוב למידע נוסף
C9: שינוי הודעת הקלט על שמות הסעיפים בגיליון תוצאות השיקוף
B10: 070620 | C10: הפיכת מחזוריות 'חודשי' ל- 'חודשי/מזדמן'
C11: אפשרות מחיקה של סיווג שגוי של תנועה לסעיף
C12: הוספת תמיכה לטעינת דפי תנועות ישראכרט
C13: בהוראות גיליון שלב א', במקום 'לסוף' -> 'אחרון'
B14: 170620 | C14: שינוי שם ל- שמיר
C15: הכנה לתמיכה בכל הפורמטים הנוספים וסידורם לפי א-ב
C16: בגיליון הדרכה - 1. הדגשה להוריד פירוט חיובי אשראי מאתר חברת האשראי. 2. הכנה לקישור לקובץ שו"ת.
B17: 240620 | C17: הוספת קישור לסרטון הדרכה
C18: ביטול הגנת חוברת עבודה עם סיסמא (הפריע ליבוא מהתוכנה)
B19: 290620 | C19: הוספת קישור לשאלות ותשובות
B20: 020720 | C20: הוספת תמיכה בפורמטים של בנק אגוד, אוצר החייל, הבינלאומי
B21: 080720 | C21: בגיליון שלב ב: גלילה כך שבפתיחה תהיה חשופה השורה הראשונה בטבלה + הוספת אזהרה לגבי שינוי סדר ומיקום של תנועות.
C22: הוספת תמיכה בפורמט בנק הפועלים.
B23: 130720 | C23: תיקון התמיכה בטעינת פורמט ישראכאט לפי זה היוצא מאתר חברת האשראי. ללא תמיכה בעסקאות בחו"ל. אלו יצטרכו להיטען ידנית בסוף.
B24: 150720 | C24: תמיכה באקסל באנגלית, החלפת מקום ריק ברשימה עבור מקורות שייתמכו בעתיד למקום שרשום בו "---- שמור זמנית ---".
B25: 030820 | C25: הוספת תמיכה בפורמט בנק מסד. שינוי אופן החישוב של שורת נתונים אחרונה בחלק מהפורמטים (לפי סוג פעולה / אסמכתא וכדו').
B26: 070820 | C26: הוספת מאקרו לכיווץ אוטומטי של רצועת הכלים בפתיחה. חושף יותר שורות וסיווג בגיליון שלב ב.
B27: 120820 | C27: שינוי החישוב בעמודה L (בשלב ב) כדי לאפשר לסווג פעולה שהוכנסה ישנית עם סכום בלבד וללא "תאור / שם בי העסק"
B28: 190820 | C28: ביטול הגנת חוברת עבודה עם סיסמא כי מפריע ליבוא מהתוכנה (בוטל כבר מגירסה 240620 אבל הוכנס בטעות בחזרה)
B29: 251020 | C29: שינוי החישוב בעמודה L (בשלב ב) כדי לספור מופעים רק כאשר יש זהות גם ב"תאור / שם בית העסק" וגם ב"שם סעיף".
C30: באפשרויות לבחירת 'מחזוריות', החלפת "אחת ל-X חודשים", ב- "חלוקת הסכום ב-X".
C31: שינוי החישוב בעמודה J (בשלב ב) כך שאם נבחר "חלוקת הסכום ב-X" החילוק ייעשה רק על בסיס X (ללא קשר לתקופת השיקוף ו/או למס' המופעים של התנועה). נותן שליטה מלאה למשתמש.
C32: התייחסות "תנועות" בצעד 2 בגיליון "שלב ב", כדי לכלול עסקאות בחו"ל אות תנועות אחרות שלא נטענו אוטומטית מתוך דף המקור.
C33: הוספת התייחסות לתנועות חו"ל בקובץ השו"ת.
B34: 061220 | C34: הוספת כפתור וקישור להורדת גירסה מעודכנת
C35: תמיכה בפורמט פועלים עסקי
C36: בגיליון שלב א' הוספת הטקסט "או אם הטעינה האוטומטית נכשלה".
B37: 150221 | C37: הגנת גיליון שלב ג
B38: 280221 | C38: מניעת שגיאה בשלב ב' במקרה שבוחרים מחזוריות ואח"כ מתחרטים ומוחקים את תוכן התא
C39: הוספת אזהרה בשלב ב' במקרה שמזינים מחזוריות שאינה מספר
B40: 230621 | C40: הוספת תמיכה בפורמט יחודי של אוצר החייל. הפורמט הקודם של אוצר החייל בעצם זהה לבינלאומי ויוכר ככזה. ראה פניה #18649.
B41: 160821 | C41: תמיכה בפורמט דף התנועות החדש של בנק לאומי
...

Sheet שמור 2 - רשימת בנקים ואשראי
A1: אין למחוק גיליון זה
A3: קוד בנק​ | B3: שם​ הבנק | C3: נתמך | F3: חברת כ. אשראי | G3: מותגים | H3: נתמך
A4: 13​ | B4: בנק אגוד לישראל בע"מ​ | C4: 1 | F4: Cal | H4: 1
A5: 14​ | B5: בנק אוצר החייל בע"מ​ | C5: 1 | G5: דיינרס
A6: 11​ | B6: בנק דיסקונט לישראל בע"מ​ | C6: 1 | G6: מסטרקארד
A7: 12​ | B7: בנק הפועלים בע"מ​ - חשבון עסקי | C7: 1 | G7: VISA
A8: 12​ | B8: בנק הפועלים בע"מ​ | C8: 1
A9: 4​ | B9: בנק יהב לעובדי המדינה בע"מ​ | C9: 1 | F9: MAX ("לאומי קארד") | H9: 1
A10: 54​ | B10: בנק ירושלים בע"מ​ | G10: VISA
A11: 10​ | B11: בנק לאומי לישראל בע"מ​ | C11: 1 | G11: מסטרקארד
A12: 30​ | B12: בנק למסחר בע"מ (לבנק מונה מפרק זמני)​ | G12: מולטי...
A13: 20​ | B13: בנק מזרחי טפחות בע"מ​ | C13: 1
A14: 46​ | B14: בנק מסד בע"מ​ | C14: 1 | F14: ישראכרט | G14: VISA | H14: 1 | I14: ללא עסקאות בחו"ל
A15: 17​ | B15: בנק מרכנתיל דיסקונט בע"מ​ | C15: 1 | G15: מסטרקארד
A16: 34​ | B16: בנק ערבי ישראלי בע"מ​ | G16: אמריקן אקספרס
A17: 52​ | B17: בנק פועלי אגודת ישראל בע"מ​
A18: 31​ | B18: הבנק הבינלאומי הראשון לישראל בע"מ​ | C18: 1
A19: 26​ | B19: יובנק בע"מ​
A20: 68​ | B20: בנק דקסיה ישראל בע"מ​

Sheet שמור4
A1: אין למחוק גיליון זה

Sheet שמור5
A1: אין למחוק גיליון זה

Sheet שמור6
A1: אין למחוק גיליון זה

Sheet שמור7
A1: אין למחוק גיליון זה

Sheet שמור8
A1: אין למחוק גיליון זה

Sheet שמור9
A1: אין למחוק גיליון זה

Sheet שמור10

Sheet ליבוא מהתוכנה
A1: [אין למחוק או לערוך גיליון זה] | I1: מוכן ליבוא | CX1: =IF(D2=AI2,"",F2) | CY1: =IF(D2=AI2,"shikuf",IF(D2=AI3,"balance","budget")) -> shikuf | CZ1: =IF(ISERROR(I1),"import_error",IF(I1="מוכן ליבוא","import_ok","import_error")) -> import_ok
CZ2: FOR PROGRAMER
CT3: ID | CU3: שם | CY3: Values | CZ3: Names
CT4: 20 | CU4: אחזקת בית - כללי | CY4: =VLOOKUP(CU4,'שלב ג - תוצאות השיקוף'!$A$4:$B$339,2,0) -> 0 | CZ4: 20
CT5: 7 | CU5: גז | CY5: =VLOOKUP(CU5,'שלב ג - תוצאות השיקוף'!$A$4:$B$339,2,0) -> 0 | CZ5: 7
CT6: 169 | CU6: גינה | CY6: =VLOOKUP(CU6,'שלב ג - תוצאות השיקוף'!$A$4:$B$339,2,0) -> 0 | CZ6: 169
CT7: 6 | CU7: חשמל | CY7: =VLOOKUP(CU7,'שלב ג - תוצאות השיקוף'!$A$4:$B$339,2,0) -> 0 | CZ7: 6
CT8: 5 | CU8: מים וביוב | CY8: =VLOOKUP(CU8,'שלב ג - תוצאות השיקוף'!$A$4:$B$339,2,0) -> 0 | CZ8: 5
CT9: 30 | CU9: ניקיון | CY9: =VLOOKUP(CU9,'שלב ג - תוצאות השיקוף'!$A$4:$B$339,2,0) -> 0 | CZ9: 30
CT10: 35 | CU10: תיקונים בבית / במכשירים | CY10: =VLOOKUP(CU10,'שלב ג - תוצאות השיקוף'!$A$4:$B$339,2,0) -> 0 | CZ10: 35
CT11: 129 | CU11: אירוע בעבודה / לחברים | CY11: =VLOOKUP(CU11,'שלב ג - תוצאות השיקוף'!$A$4:$B$339,2,0) -> 0 | CZ11: 129
CT12: 27 | CU12: חגים וצרכי דת | CX12: =F12 -> 0 | CY12: =VLOOKUP(CU12,'שלב ג - תוצאות השיקוף'!$A$4:$B$339,2,0) -> 0 | CZ12: 27
CT13: 18 | CU13: תרומות | CX13: =F13 -> 0 | CY13: =VLOOKUP(CU13,'שלב ג - תוצאות השיקוף'!$A$4:$B$339,2,0) -> 0 | CZ13: 18
CT14: 119 | CU14: ביגוד הורים | CY14: =VLOOKUP(CU14,'שלב ג - תוצאות השיקוף'!$A$4:$B$339,2,0) -> 0 | CZ14: 119
CT15: 29 | CU15: ביגוד והנעלה - כללי | CY15: =VLOOKUP(CU15,'שלב ג - תוצאות השיקוף'!$A$4:$B$339,2,0) -> 0 | CZ15: 29
CT16: 121 | CU16: ביגוד ילדים | CY16: =VLOOKUP(CU16,'שלב ג - תוצאות השיקוף'!$A$4:$B$339,2,0) -> 0 | CZ16: 121
CT17: 158 | CU17: נעליים | CY17: =VLOOKUP(CU17,'שלב ג - תוצאות השיקוף'!$A$4:$B$339,2,0) -> 0 | CZ17: 158
CT18: 13 | CU18: אופטיקה | CY18: =VLOOKUP(CU18,'שלב ג - תוצאות השיקוף'!$A$4:$B$339,2,0) -> 0 | CZ18: 13
CT19: 162 | CU19: ביטוח רפואי נוסף | CY19: =VLOOKUP(CU19,'שלב ג - תוצאות השיקוף'!$A$4:$B$339,2,0) -> 0 | CZ19: 162
CT20: 12 | CU20: בריאות - כללי | CY20: =VLOOKUP(CU20,'שלב ג - תוצאות השיקוף'!$A$4:$B$339,2,0) -> 0 | CZ20: 12
CT21: 14 | CU21: טיפולי שיניים | CY21: =VLOOKUP(CU21,'שלב ג - תוצאות השיקוף'!$A$4:$B$339,2,0) -> #N/A | CZ21: 14
CT22: 67 | CU22: טיפולים פרטיים | CY22: =VLOOKUP(CU22,'שלב ג - תוצאות השיקוף'!$A$4:$B$339,2,0) -> 0 | CZ22: 67
CT23: 56 | CU23: קופ"ח תשלום קבוע | CY23: =VLOOKUP(CU23,'שלב ג - תוצאות השיקוף'!$A$4:$B$339,2,0) -> 0 | CZ23: 56
CT24: 68 | CU24: תרופות | CY24: =VLOOKUP(CU24,'שלב ג - תוצאות השיקוף'!$A$4:$B$339,2,0) -> 0 | CZ24: 68
CT25: 4 | CU25: ארנונה | CY25: =VLOOKUP(CU25,'שלב ג - תוצאות השיקוף'!$A$4:$B$339,2,0) -> 0 | CZ25: 4
... CT33: 143 | CU33: בית ספר | CY33: =VLOOKUP(CU33,'שלב ג - תוצאות השיקוף'!$A$4:$B$339,2,0) -> 0 | CZ33: 143
CT34: 142 | CU34: הסעות | CX34: =F34 -> 0 | CY34: =VLOOKUP(CU34,'שלב ג - תוצאות השיקוף'!$A$4:$B$339,2,0) -> 0 | CZ34: 142
CT35: 11 | CU35: חוגים ותנועת נוער | CX35: =F35 -> 0 | CY35: =VLOOKUP(CU35,'שלב ג - תוצאות השיקוף'!$A$4:$B$339,2,0) -> 0 | CZ35: 11
CT36: 10 | CU36: חינוך - כללי | CY36: =VLOOKUP(CU36,'שלב ג - תוצאות השיקוף'!$A$4:$B$339,2,0) -> 0 | CZ36: 10
CT37: 62 | CU37: לימודים והשתלמות לבוגרים | CY37: =VLOOKUP(CU37,'שלב ג - תוצאות השיקוף'!$A$4:$B$339,2,0) -> 0 | CZ37: 62
CT38: 32993 | CU38: מסגרות יום | CY38: =VLOOKUP(CU38,'שלב ג - תוצאות השיקוף'!$A$4:$B$339,2,0) -> 0 | CZ38: 32993
CT39: 57 | CU39: מסגרות צהריים | CY39: =VLOOKUP(CU39,'שלב ג - תוצאות השיקוף'!$A$4:$B$339,2,0) -> 0 | CZ39: 57
CT40: 59 | CU40: מסגרות קיץ | CY40: =VLOOKUP(CU40,'שלב ג - תוצאות השיקוף'!$A$4:$B$339,2,0) -> 0 | CZ40: 59
CT41: 144 | CU41: צהרון / מטפלת | CY41: =VLOOKUP(CU41,'שלב ג - תוצאות השיקוף'!$A$4:$B$339,2,0) -> 0 | CZ41: 144
CT42: 145 | CU42: שיעור פרטי | CY42: =VLOOKUP(CU42,'שלב ג - תוצאות השיקוף'!$A$4:$B$339,2,0) -> 0 | CZ42: 145
CT43: 33000 | CU43: טיפוח - כללי | CY43: =VLOOKUP(CU43,'שלב ג - תוצאות השיקוף'!$A$4:$B$339,2,0) -> 0 | CZ43: 33000
CT44: 34 | CU44: מספרה | CY44: =VLOOKUP(CU44,'שלב ג - תוצאות השיקוף'!$A$4:$B$339,2,0) -> 0 | CZ44: 34
CT45: 32999 | CU45: קוסמטיקה | CX45: =F45 -> 0 | CY45: =VLOOKUP(CU45,'שלב ג - תוצאות השיקוף'!$A$4:$B$339,2,0) -> 0 | CZ45: 32999
